Workbook

Sheet Start here
A1: Your own company - what it would actually take, and what it would actually make
A4: This is the private file. It is the plan for the version of your life where, somewhere around 24 to 26, you start your own drainage and excavation company in Baton Rouge instead of - or as well as - taking a stake in Charlie's.
A6: Every number in here is a formula off blue cells you can change. Nothing is a promise. But every default has a source, and the sources tab is at the end.
A8: Read this before the numbers:
A10: 1. Most contractors who start a company are still in business after year one - about 80% - and about 62% are still there after five. The ones that fail almost never fail because they could not dig. They run out of cash, they bid too low, or they grow faster than their money. This file is built to keep you in the 62%, which mostly means starting with more working capital than feels necessary and pricing higher than feels comfortable.
A12: 2. Other people's money is real, and it is available to you - but in a specific order, and not all at once. At 22 with two years of credit history you can genuinely get a 0% Kiva loan, a microloan up to $50,000, and a used-equipment loan with 20% down. You cannot get a bank line or a full SBA 7(a) until you have two filed tax returns. The 'Loans and credit ladder' tab says exactly what you can get at what age, so you apply for the right thing and never collect ten declines.
A14: 3. Credit is built years before it is used. The single most valuable thing you can do for the version of you at 24 is to open a secured card the week you turn 18 and never once pay it late. That is not a metaphor. Lenders in 2032 will price your equipment loan off what you did in November 2026.
A16: 4. There is no investor for this. Nobody buys equity in a one-crew excavation company, and you would not want them to. The money for this comes from your savings, from lenders who are repaid, and possibly from family on a written note at a fair rate. The tab called 'What it is worth' explains what a partner deal should look like if one ever comes up - and why it should be a lease or a note, not a share of the company.
A18: 5. The plan works whether you do this or not. Every skill and licence on the way to it is yours regardless. If at 25 the better move is a stake in Scag Scapes, this file has still done its job - it told you what your alternative was worth, which is the only way to negotiate.
A20: Tabs: Assumptions (every blue cell) -> Ten-year proforma -> Startup budget and funding -> Loans and credit ladder -> Owner pay and write-offs -> What it is worth -> Sources.

Sheet Assumptions
A1: Assumptions - every blue cell drives every other tab
A2: Blue = change it. Yellow = the levers that matter most. Black = formula.
A4: WHEN AND HOW YOU START
A5: Age when you open the company | B5: 25 | C5: Around when the ladder in your other file has you at foreman with your first machine. Move it if you are ready sooner or want longer inside Scag Scapes first.
A6: Cash you bring in from savings ($) | B6: 35000 | C6: From the Money tab in your other file - what the savings plan gets you to by then. This is your equity injection; lenders want to see it before they lend.
A7: You work in the field yourself in years 1-3 (1 = yes, 0 = no) | B7: 1 | C7: An owner-operator on crew 1 saves a wage and is the normal way this starts. The model stops charging for one crew member on crew 1 while this is 1.
A8: THE WORK
A9: Crews in year 1 | B9: 1
A10: Add one more crew every N years | B10: 3 | C10: Crew 2 in year 4, crew 3 in year 7 on the default. Each new crew needs an equipment set (below) and is the biggest single decision in this file.
A11: Maximum crews | B11: 3 | C11: Three crews is a real, profitable, sellable company that one owner can still run without a manager. Past that is a different business.
A12: Linear feet a crew installs per working day | B12: 42 | C12: Charlie's crews target 43 at maturity. A new crew with a new owner runs slower.
A13: Working days a year | B13: 240 | C13: Weather, holidays, downtime. Baton Rouge loses real days to rain; 240 is about what an established crew actually works.
A14: Utilisation in year 1 (share of days actually sold) | B14: 0.6 | C14: The first year you do not have a pipeline. This is the honest haircut, and it rises to the number below over three years.
A15: Utilisation once established | B15: 0.85
A16: Price per linear foot installed ($) | B16: 48 | C16: Louisiana french drain pricing runs $23-90/LF; Charlie sells around $50. A new company without reviews prices a little under an established one - but NOT a lot under. Underbidding is the second-biggest killer.
A17: Price increase per year | B17: 0.03
A18: PEOPLE
A19: Crew size (people, including you if you are in the field) | B19: 3
A20: Crew wage ($/hr) | B20: 24 | C20: Above the Baton Rouge labourer median of $18.58 so you can keep people - the same logic Charlie uses. You will have learned by then that turnover costs about 21% of a salary per person.
A21: Paid hours per crew member per year | B21: 2000
A22: Payroll burden (taxes, workers comp, insurance) | B22: 0.2 | C22: Workers comp for excavation (class 6217) runs about $5.25 per $100 of payroll nationally; Louisiana loss costs fell 5.3% in 2026. 20% all-in burden is realistic for this class.
A23: Wage increase per year | B23: 0.035 | C23: Baton Rouge specialty-trade wages actually grew 3.75%/yr 2019-2024. 3.5% is the conservative case.
A24: COSTS
A25: Materials and fuel (share of revenue) | B25: 0.21 | C25: Pipe, fabric, aggregate, diesel. Charlie runs about 20%; a smaller buyer pays slightly more for aggregate.
A26: Insurance - general liability, auto, equipment floater ($/yr, first crew) | B26: 14000 | C26: A small-excavator programme runs $12-35K/yr all-in. GL of at least $100,000 is a licence requirement in Louisiana. This is the first-crew figure; each added crew adds the amount below.
A27: Insurance added per extra crew ($/yr) | B27: 7000
A28: Truck, fuel for estimates, phone, software ($/mo) | B28: 900 | C28: Your truck's business miles are reimbursed by the company to you - a deductible expense here, tax-free income to you personally.
A29: Marketing (share of revenue) | B29: 0.05 | C29: Google Local Services Ads run about $53 a lead for home services. Reviews are free and matter more.
A30: Bookkeeping, CPA, licence renewals ($/mo) | B30: 300 | C30: Do not skip the CPA. The write-offs tab is worth several times this.
A31: Yard, shop, tools replacement, misc ($/mo) | B31: 600
A32: General cost increase per year | B32: 0.0275
A33: YOUR PAY
A34: Your own salary in year 1 ($/yr) | B34: 55000 | C34: Less than you would earn as a foreman for somebody else - and that is normal in year 1 of any company. It rises with the business below. See the Owner pay tab for what this is after tax and write-offs.
A35: Your salary increase per year | B35: 0.08 | C35: Faster than inflation on purpose - you are underpaid in year 1 and catching up.
A36: EQUIPMENT
A37: Equipment set for a crew ($) - used mini-ex, used track loader, trailer, tools | B37: 80000 | C37: Used Bobcat E35 class $32-44K; used T650 class $27-32K; 14,000 lb trailer $6,200; tools, pump, laser $6,000. About $80K used. New would be roughly double.
A38: Down payment on financed equipment | B38: 0.2 | C38: Independent lenders want 10-25% down from a young business. 20% is the realistic ask.
A39: Equipment loan rate (APR) | B39: 0.14 | C39: A first-time owner with 2 years of history and a 700+ score pays 3-8 points over an established contractor - 13-18% is the honest range. It comes down with every year of clean payment history.
A40: Equipment loan term (years) | B40: 5
A41: Equipment written off over (years, for tax) | B41: 5 | C41: Section 179 lets you expense it in year one if that is better - ask the CPA which. The model uses straight-line for the tax estimate to stay conservative.
...

Sheet Ten-year proforma
A1: Ten years, from the day you open the doors
A2: Every figure is a formula off the Assumptions tab. Change a blue cell there and all ten years move.
A5: Year | B5: 1 | C5: 2 | D5: 3 | E5: 4 | F5: 5 | G5: 6 | H5: 7 | I5: 8 | J5: 9 | K5: 10 | M5: Notes
A6: Your age | B6: =Assumptions!$B$5+0 -> 25 | C6: =Assumptions!$B$5+1 -> 26 | D6: =Assumptions!$B$5+2 -> 27 | E6: =Assumptions!$B$5+3 -> 28 | F6: =Assumptions!$B$5+4 -> 29 | G6: =Assumptions!$B$5+5 -> 30 | H6: =Assumptions!$B$5+6 -> 31 | I6: =Assumptions!$B$5+7 -> 32 | J6: =Assumptions!$B$5+8 -> 33 | K6: =Assumptions!$B$5+9 -> 34
A7: THE WORK
A8: Crews running | B8: =MIN(Assumptions!$B$11,Assumptions!$B$9+INT(0/Assumptions!$B$10)) -> 1 | C8: =MIN(Assumptions!$B$11,Assumptions!$B$9+INT(1/Assumptions!$B$10)) -> 1 | D8: =MIN(Assumptions!$B$11,Assumptions!$B$9+INT(2/Assumptions!$B$10)) -> 1 | E8: =MIN(Assumptions!$B$11,Assumptions!$B$9+INT(3/Assumptions!$B$10)) -> 2 | F8: =MIN(Assumptions!$B$11,Assumptions!$B$9+INT(4/Assumptions!$B$10)) -> 2 | G8: =MIN(Assumptions!$B$11,Assumptions!$B$9+INT(5/Assumptions!$B$10)) -> 2 | H8: =MIN(Assumptions!$B$11,Assumptions!$B$9+INT(6/Assumptions!$B$10)) -> 3 | I8: =MIN(Assumptions!$B$11,Assumptions!$B$9+INT(7/Assumptions!$B$10)) -> 3 | J8: =MIN(Assumptions!$B$11,Assumptions!$B$9+INT(8/Assumptions!$B$10)) -> 3 | K8: =MIN(Assumptions!$B$11,Assumptions!$B$9+INT(9/Assumptions!$B$10)) -> 3 | M8: Crew 2 arrives when the Assumptions tab says. Every new crew triggers an equipment set and a loan below.
A9: Utilisation (share of days sold) | B9: =MIN(Assumptions!$B$15,Assumptions!$B$14+(Assumptions!$B$15-Assumptions!$B$14)*0) -> 0.6 | C9: =MIN(Assumptions!$B$15,Assumptions!$B$14+(Assumptions!$B$15-Assumptions!$B$14)*0.5) -> 0.725 | D9: =MIN(Assumptions!$B$15,Assumptions!$B$14+(Assumptions!$B$15-Assumptions!$B$14)*1) -> 0.85 | E9: =MIN(Assumptions!$B$15,Assumptions!$B$14+(Assumptions!$B$15-Assumptions!$B$14)*1) -> 0.85 | F9: =MIN(Assumptions!$B$15,Assumptions!$B$14+(Assumptions!$B$15-Assumptions!$B$14)*1) -> 0.85 | G9: =MIN(Assumptions!$B$15,Assumptions!$B$14+(Assumptions!$B$15-Assumptions!$B$14)*1) -> 0.85 | H9: =MIN(Assumptions!$B$15,Assumptions!$B$14+(Assumptions!$B$15-Assumptions!$B$14)*1) -> 0.85 | I9: =MIN(Assumptions!$B$15,Assumptions!$B$14+(Assumptions!$B$15-Assumptions!$B$14)*1) -> 0.85 | J9: =MIN(Assumptions!$B$15,Assumptions!$B$14+(Assumptions!$B$15-Assumptions!$B$14)*1) -> 0.85 | K9: =MIN(Assumptions!$B$15,Assumptions!$B$14+(Assumptions!$B$15-Assumptions!$B$14)*1) -> 0.85 | M9: Ramps from the year-1 figure to the established figure over three years. A pipeline takes time to build and this is where a new company most often fools itself.
A10: Linear feet installed | B10: =B8*Assumptions!$B$12*Assumptions!$B$13*B9 -> 6048 | C10: =C8*Assumptions!$B$12*Assumptions!$B$13*C9 -> 7308 | D10: =D8*Assumptions!$B$12*Assumptions!$B$13*D9 -> 8568 | E10: =E8*Assumptions!$B$12*Assumptions!$B$13*E9 -> 17136 | F10: =F8*Assumptions!$B$12*Assumptions!$B$13*F9 -> 17136 | G10: =G8*Assumptions!$B$12*Assumptions!$B$13*G9 -> 17136 | H10: =H8*Assumptions!$B$12*Assumptions!$B$13*H9 -> 25704 | I10: =I8*Assumptions!$B$12*Assumptions!$B$13*I9 -> 25704 | ... K10: =K8*Assumptions!$B$12*Assumptions!$B$13*K9 -> 25704
A11: Price per linear foot | B11: =Assumptions!$B$16*(1+Assumptions!$B$17)^0 -> 48 | C11: =Assumptions!$B$16*(1+Assumptions!$B$17)^1 -> 49.44 | D11: =Assumptions!$B$16*(1+Assumptions!$B$17)^2 -> 50.9232 | E11: =Assumptions!$B$16*(1+Assumptions!$B$17)^3 -> 52.450896 | F11: =Assumptions!$B$16*(1+Assumptions!$B$17)^4 -> 54.024423 | G11: =Assumptions!$B$16*(1+Assumptions!$B$17)^5 -> 55.645156 | H11: =Assumptions!$B$16*(1+Assumptions!$B$17)^6 -> 57.31451 | I11: =Assumptions!$B$16*(1+Assumptions!$B$17)^7 -> 59.033946 | J11: =Assumptions!$B$16*(1+Assumptions!$B$17)^8 -> 60.804964 | K11: =Assumptions!$B$16*(1+Assumptions!$B$17)^9 -> 62.629113
A12: REVENUE | B12: =B10*B11 -> 290304 | C12: =C10*C11 -> 361307.52 | D12: =D10*D11 -> 436309.98 | E12: =E10*E11 -> 898798.55 | F12: =F10*F11 -> 925762.51 | G12: =G10*G11 -> 953535.39 | H12: =H10*H11 -> 1473212.2 | I12: =I10*I11 -> 1517408.5 | ... K12: =K10*K11 -> 1609818.7 | M12: One crew at 40 LF a day, 60% sold in year 1, at $48 - about $260K. That matches what a one-crew drainage start-up in Louisiana can realistically expect ($250-350K).
A13: WHAT IT COSTS TO DO THE WORK
A14: Paid crew members | B14: =B8*Assumptions!$B$19-IF(AND(Assumptions!$B$7=1,1<=3),1,0) -> 2 | C14: =C8*Assumptions!$B$19-IF(AND(Assumptions!$B$7=1,2<=3),1,0) -> 2 | D14: =D8*Assumptions!$B$19-IF(AND(Assumptions!$B$7=1,3<=3),1,0) -> 2 | E14: =E8*Assumptions!$B$19-IF(AND(Assumptions!$B$7=1,4<=3),1,0) -> 6 | F14: =F8*Assumptions!$B$19-IF(AND(Assumptions!$B$7=1,5<=3),1,0) -> 6 | G14: =G8*Assumptions!$B$19-IF(AND(Assumptions!$B$7=1,6<=3),1,0) -> 6 | H14: =H8*Assumptions!$B$19-IF(AND(Assumptions!$B$7=1,7<=3),1,0) -> 9 | I14: =I8*Assumptions!$B$19-IF(AND(Assumptions!$B$7=1,8<=3),1,0) -> 9 | J14: =J8*Assumptions!$B$19-IF(AND(Assumptions!$B$7=1,9<=3),1,0) -> 9 | K14: =K8*Assumptions!$B$19-IF(AND(Assumptions!$B$7=1,10<=3),1,0) -> 9 | M14: One fewer paid seat while you are in the field yourself in years 1-3.
A15: Crew labour (wages plus burden) | B15: =B14*Assumptions!$B$21*Assumptions!$B$20*(1+Assumptions!$B$22)*(1+Assumptions!$B$23)^0 -> 115200 | C15: =C14*Assumptions!$B$21*Assumptions!$B$20*(1+Assumptions!$B$22)*(1+Assumptions!$B$23)^1 -> 119232 | D15: =D14*Assumptions!$B$21*Assumptions!$B$20*(1+Assumptions!$B$22)*(1+Assumptions!$B$23)^2 -> 123405.12 | E15: =E14*Assumptions!$B$21*Assumptions!$B$20*(1+Assumptions!$B$22)*(1+Assumptions!$B$23)^3 -> 383172.9 | F15: =F14*Assumptions!$B$21*Assumptions!$B$20*(1+Assumptions!$B$22)*(1+Assumptions!$B$23)^4 -> 396583.95 | G15: =G14*Assumptions!$B$21*Assumptions!$B$20*(1+Assumptions!$B$22)*(1+Assumptions!$B$23)^5 -> 410464.39 | H15: =H14*Assumptions!$B$21*Assumptions!$B$20*(1+Assumptions!$B$22)*(1+Assumptions!$B$23)^6 -> 637245.96 | I15: =I14*Assumptions!$B$21*Assumptions!$B$20*(1+Assumptions!$B$22)*(1+Assumptions!$B$23)^7 -> 659549.57 | J15: =J14*Assumptions!$B$21*Assumptions!$B$20*(1+Assumptions!$B$22)*(1+Assumptions!$B$23)^8 -> 682633.8 | K15: =K14*Assumptions!$B$21*Assumptions!$B$20*(1+Assumptions!$B$22)*(1+Assumptions!$B$23)^9 -> 706525.99
A16: Materials and fuel | B16: =B12*Assumptions!$B$25 -> 60963.84 | C16: =C12*Assumptions!$B$25 -> 75874.579 | D16: =D12*Assumptions!$B$25 -> 91625.095 | E16: =E12*Assumptions!$B$25 -> 188747.7 | F16: =F12*Assumptions!$B$25 -> 194410.13 | G16: =G12*Assumptions!$B$25 -> 200242.43 | H16: =H12*Assumptions!$B$25 -> 309374.56 | I16: =I12*Assumptions!$B$25 -> 318655.79 | ... K16: =K12*Assumptions!$B$25 -> 338061.93
A17: GROSS PROFIT | B17: =B12-B15-B16 -> 114140.16 | C17: =C12-C15-C16 -> 166200.94 | D17: =D12-D15-D16 -> 221279.76 | E17: =E12-E15-E16 -> 326877.96 | F17: =F12-F15-F16 -> 334768.43 | G17: =G12-G15-G16 -> 342828.57 | H17: =H12-H15-H16 -> 526591.65 | I17: =I12-I15-I16 -> 539203.17 | ... K17: =K12-K15-K16 -> 565230.8
A18: Gross margin | B18: =IF(B12=0,0,B17/B12) -> 0.3931746 | C18: =IF(C12=0,0,C17/C12) -> 0.45999857 | D18: =IF(D12=0,0,D17/D12) -> 0.50716182 | E18: =IF(E12=0,0,E17/E12) -> 0.36368323 | F18: =IF(F12=0,0,F17/F12) -> 0.36161373 | G18: =IF(G12=0,0,G17/G12) -> 0.35953418 | H18: =IF(H12=0,0,H17/H12) -> 0.35744454 | I18: =IF(I12=0,0,I17/I12) -> 0.35534476 | ... K18: =IF(K12=0,0,K17/K12) -> 0.35111456 | M18: Charlie's rule is 50%. A new company with you on the crew can beat it early because you are not paying yourself a crew wage.
A19: OVERHEAD - THE BILLS THAT ARRIVE WHETHER YOU DIG OR NOT
A20: Insurance | B20: =(Assumptions!$B$26+Assumptions!$B$27*MAX(0,B8-1))*(1+Assumptions!$B$32)^0 -> 14000 | C20: =(Assumptions!$B$26+Assumptions!$B$27*MAX(0,C8-1))*(1+Assumptions!$B$32)^1 -> 14385 | D20: =(Assumptions!$B$26+Assumptions!$B$27*MAX(0,D8-1))*(1+Assumptions!$B$32)^2 -> 14780.587 | E20: =(Assumptions!$B$26+Assumptions!$B$27*MAX(0,E8-1))*(1+Assumptions!$B$32)^3 -> 22780.58 | F20: =(Assumptions!$B$26+Assumptions!$B$27*MAX(0,F8-1))*(1+Assumptions!$B$32)^4 -> 23407.046 | G20: =(Assumptions!$B$26+Assumptions!$B$27*MAX(0,G8-1))*(1+Assumptions!$B$32)^5 -> 24050.74 | H20: =(Assumptions!$B$26+Assumptions!$B$27*MAX(0,H8-1))*(1+Assumptions!$B$32)^6 -> 32949.514 | I20: =(Assumptions!$B$26+Assumptions!$B$27*MAX(0,I8-1))*(1+Assumptions!$B$32)^7 -> 33855.626 | J20: =(Assumptions!$B$26+Assumptions!$B$27*MAX(0,J8-1))*(1+Assumptions!$B$32)^8 -> 34786.655 | K20: =(Assumptions!$B$26+Assumptions!$B$27*MAX(0,K8-1))*(1+Assumptions!$B$32)^9 -> 35743.288
A21: Truck, fuel, phone, software | B21: =Assumptions!$B$28*12*(1+Assumptions!$B$32)^0*(0.6+0.4*B8) -> 10800 | C21: =Assumptions!$B$28*12*(1+Assumptions!$B$32)^1*(0.6+0.4*C8) -> 11097 | D21: =Assumptions!$B$28*12*(1+Assumptions!$B$32)^2*(0.6+0.4*D8) -> 11402.167 | E21: =Assumptions!$B$28*12*(1+Assumptions!$B$32)^3*(0.6+0.4*E8) -> 16402.018 | F21: =Assumptions!$B$28*12*(1+Assumptions!$B$32)^4*(0.6+0.4*F8) -> 16853.073 | G21: =Assumptions!$B$28*12*(1+Assumptions!$B$32)^5*(0.6+0.4*G8) -> 17316.533 | H21: =Assumptions!$B$28*12*(1+Assumptions!$B$32)^6*(0.6+0.4*H8) -> 22876.377 | I21: =Assumptions!$B$28*12*(1+Assumptions!$B$32)^7*(0.6+0.4*I8) -> 23505.477 | J21: =Assumptions!$B$28*12*(1+Assumptions!$B$32)^8*(0.6+0.4*J8) -> 24151.878 | K21: =Assumptions!$B$28*12*(1+Assumptions!$B$32)^9*(0.6+0.4*K8) -> 24816.055
A22: Marketing | B22: =B12*Assumptions!$B$29 -> 14515.2 | C22: =C12*Assumptions!$B$29 -> 18065.376 | D22: =D12*Assumptions!$B$29 -> 21815.499 | E22: =E12*Assumptions!$B$29 -> 44939.928 | F22: =F12*Assumptions!$B$29 -> 46288.126 | G22: =G12*Assumptions!$B$29 -> 47676.769 | H22: =H12*Assumptions!$B$29 -> 73660.609 | I22: =I12*Assumptions!$B$29 -> 75870.427 | ... K22: =K12*Assumptions!$B$29 -> 80490.936
A23: Bookkeeping, CPA, licences | B23: =Assumptions!$B$30*12*(1+Assumptions!$B$32)^0 -> 3600 | C23: =Assumptions!$B$30*12*(1+Assumptions!$B$32)^1 -> 3699 | D23: =Assumptions!$B$30*12*(1+Assumptions!$B$32)^2 -> 3800.7225 | E23: =Assumptions!$B$30*12*(1+Assumptions!$B$32)^3 -> 3905.2424 | F23: =Assumptions!$B$30*12*(1+Assumptions!$B$32)^4 -> 4012.6365 | G23: =Assumptions!$B$30*12*(1+Assumptions!$B$32)^5 -> 4122.984 | H23: =Assumptions!$B$30*12*(1+Assumptions!$B$32)^6 -> 4236.3661 | I23: =Assumptions!$B$30*12*(1+Assumptions!$B$32)^7 -> 4352.8662 | J23: =Assumptions!$B$30*12*(1+Assumptions!$B$32)^8 -> 4472.57 | K23: =Assumptions!$B$30*12*(1+Assumptions!$B$32)^9 -> 4595.5657
A24: Yard, shop, tools, misc | B24: =Assumptions!$B$31*12*(1+Assumptions!$B$32)^0*(0.7+0.3*B8) -> 7200 | C24: =Assumptions!$B$31*12*(1+Assumptions!$B$32)^1*(0.7+0.3*C8) -> 7398 | D24: =Assumptions!$B$31*12*(1+Assumptions!$B$32)^2*(0.7+0.3*D8) -> 7601.445 | E24: =Assumptions!$B$31*12*(1+Assumptions!$B$32)^3*(0.7+0.3*E8) -> 10153.63 | F24: =Assumptions!$B$31*12*(1+Assumptions!$B$32)^4*(0.7+0.3*F8) -> 10432.855 | G24: =Assumptions!$B$31*12*(1+Assumptions!$B$32)^5*(0.7+0.3*G8) -> 10719.759 | H24: =Assumptions!$B$31*12*(1+Assumptions!$B$32)^6*(0.7+0.3*H8) -> 13556.372 | I24: =Assumptions!$B$31*12*(1+Assumptions!$B$32)^7*(0.7+0.3*I8) -> 13929.172 | J24: =Assumptions!$B$31*12*(1+Assumptions!$B$32)^8*(0.7+0.3*J8) -> 14312.224 | K24: =Assumptions!$B$31*12*(1+Assumptions!$B$32)^9*(0.7+0.3*K8) -> 14705.81
A25: YOUR SALARY | B25: =Assumptions!$B$34*(1+Assumptions!$B$35)^0 -> 55000 | C25: =Assumptions!$B$34*(1+Assumptions!$B$35)^1 -> 59400 | D25: =Assumptions!$B$34*(1+Assumptions!$B$35)^2 -> 64152 | E25: =Assumptions!$B$34*(1+Assumptions!$B$35)^3 -> 69284.16 | F25: =Assumptions!$B$34*(1+Assumptions!$B$35)^4 -> 74826.893 | G25: =Assumptions!$B$34*(1+Assumptions!$B$35)^5 -> 80813.044 | H25: =Assumptions!$B$34*(1+Assumptions!$B$35)^6 -> 87278.088 | I25: =Assumptions!$B$34*(1+Assumptions!$B$35)^7 -> 94260.335 | J25: =Assumptions!$B$34*(1+Assumptions!$B$35)^8 -> 101801.16 | K25: =Assumptions!$B$34*(1+Assumptions!$B$35)^9 -> 109945.25 | M25: What you pay yourself. Set on Assumptions. The Owner pay tab shows what it is after tax and what the write-offs do to it.
A26: Total overhead including your salary | B26: =B20+B21+B22+B23+B24+B25 -> 105115.2 | C26: =C20+C21+C22+C23+C24+C25 -> 114044.38 | D26: =D20+D21+D22+D23+D24+D25 -> 123552.42 | E26: =E20+E21+E22+E23+E24+E25 -> 167465.56 | F26: =F20+F21+F22+F23+F24+F25 -> 175820.63 | G26: =G20+G21+G22+G23+G24+G25 -> 184699.83 | H26: =H20+H21+H22+H23+H24+H25 -> 234557.32 | I26: =I20+I21+I22+I23+I24+I25 -> 245773.9 | ... K26: =K20+K21+K22+K23+K24+K25 -> 270296.91
A27: OPERATING PROFIT after your salary (EBITDA) | B27: =B17-B26 -> 9024.96 | C27: =C17-C26 -> 52156.565 | D27: =D17-D26 -> 97727.341 | E27: =E17-E26 -> 159412.4 | F27: =F17-F26 -> 158947.8 | G27: =G17-G26 -> 158128.74 | H27: =H17-H26 -> 292034.33 | I27: =I17-I26 -> 293429.27 | ... K27: =K17-K26 -> 294933.89 | M27: What is left after everybody including you is paid, before loans and tax. Negative in year 1 is normal and it is exactly why the working capital on the funding tab exists.
A28: EQUIPMENT AND LOANS
A29: Equipment sets bought this year | B29: =B8 -> 1 | C29: =MAX(0,C8-B8) -> 0 | D29: =MAX(0,D8-C8) -> 0 | E29: =MAX(0,E8-D8) -> 1 | F29: =MAX(0,F8-E8) -> 0 | G29: =MAX(0,G8-F8) -> 0 | H29: =MAX(0,H8-G8) -> 1 | I29: =MAX(0,I8-H8) -> 0 | J29: =MAX(0,J8-I8) -> 0 | K29: =MAX(0,K8-J8) -> 0 | M29: Year 1 is the first set. After that, one per new crew.
A30: Equipment bought this year ($, at today's used prices grown with inflation) | B30: =B29*Assumptions!$B$37*(1+Assumptions!$B$32)^0 -> 80000 | C30: =C29*Assumptions!$B$37*(1+Assumptions!$B$32)^1 -> 0 | D30: =D29*Assumptions!$B$37*(1+Assumptions!$B$32)^2 -> 0 | E30: =E29*Assumptions!$B$37*(1+Assumptions!$B$32)^3 -> 86783.164 | F30: =F29*Assumptions!$B$37*(1+Assumptions!$B$32)^4 -> 0 | G30: =G29*Assumptions!$B$37*(1+Assumptions!$B$32)^5 -> 0 | H30: =H29*Assumptions!$B$37*(1+Assumptions!$B$32)^6 -> 94141.469 | I30: =I29*Assumptions!$B$37*(1+Assumptions!$B$32)^7 -> 0 | J30: =J29*Assumptions!$B$37*(1+Assumptions!$B$32)^8 -> 0 | K30: =K29*Assumptions!$B$37*(1+Assumptions!$B$32)^9 -> 0
A31: Down payment paid in cash (year 1 is already paid on the funding tab) | B31: =0 -> 0 | C31: =C30*Assumptions!$B$38 -> 0 | D31: =D30*Assumptions!$B$38 -> 0 | E31: =E30*Assumptions!$B$38 -> 17356.633 | F31: =F30*Assumptions!$B$38 -> 0 | G31: =G30*Assumptions!$B$38 -> 0 | H31: =H30*Assumptions!$B$38 -> 18828.294 | I31: =I30*Assumptions!$B$38 -> 0 | J31: =J30*Assumptions!$B$38 -> 0 | K31: =K30*Assumptions!$B$38 -> 0 | M31: The first set's down payment came out of the sources on the funding tab, so it is not charged again here. Later sets are paid from the company's own cash.
A32: Annual payment on the loans taken THIS year | B32: =IF(B30=0,0,PMT(Assumptions!$B$39/12,Assumptions!$B$40*12,-B30*(1-Assumptions!$B$38))*12) -> 17870.017 | C32: =IF(C30=0,0,PMT(Assumptions!$B$39/12,Assumptions!$B$40*12,-C30*(1-Assumptions!$B$38))*12) -> 0 | D32: =IF(D30=0,0,PMT(Assumptions!$B$39/12,Assumptions!$B$40*12,-D30*(1-Assumptions!$B$38))*12) -> 0 | E32: =IF(E30=0,0,PMT(Assumptions!$B$39/12,Assumptions!$B$40*12,-E30*(1-Assumptions!$B$38))*12) -> 19385.207 | F32: =IF(F30=0,0,PMT(Assumptions!$B$39/12,Assumptions!$B$40*12,-F30*(1-Assumptions!$B$38))*12) -> 0 | G32: =IF(G30=0,0,PMT(Assumptions!$B$39/12,Assumptions!$B$40*12,-G30*(1-Assumptions!$B$38))*12) -> 0 | H32: =IF(H30=0,0,PMT(Assumptions!$B$39/12,Assumptions!$B$40*12,-H30*(1-Assumptions!$B$38))*12) -> 21028.87 | I32: =IF(I30=0,0,PMT(Assumptions!$B$39/12,Assumptions!$B$40*12,-I30*(1-Assumptions!$B$38))*12) -> 0 | ... K32: =IF(K30=0,0,PMT(Assumptions!$B$39/12,Assumptions!$B$40*12,-K30*(1-Assumptions!$B$38))*12) -> 0 | M32: Principal and interest, at the equipment rate on Assumptions.
A33: Debt service on equipment loans | B33: =IF(1<=Assumptions!$B$40,B32,0) -> 17870.017 | C33: =IF(2<=Assumptions!$B$40,B32,0)+IF(1<=Assumptions!$B$40,C32,0) -> 17870.017 | D33: =IF(3<=Assumptions!$B$40,B32,0)+IF(2<=Assumptions!$B$40,C32,0)+IF(1<=Assumptions!$B$40,D32,0) -> 17870.017 | E33: =IF(4<=Assumptions!$B$40,B32,0)+IF(3<=Assumptions!$B$40,C32,0)+IF(2<=Assumptions!$B$40,D32,0)+IF(1<=Assumptions!$B$40,E32,0) -> 37255.224 | F33: =IF(5<=Assumptions!$B$40,B32,0)+IF(4<=Assumptions!$B$40,C32,0)+IF(3<=Assumptions!$B$40,D32,0)+IF(2<=Assumptions!$B$40,E32,0)+IF(1<=Assumptions!$B$40,F32,0) -> 37255.224 | G33: =IF(6<=Assumptions!$B$40,B32,0)+IF(5<=Assumptions!$B$40,C32,0)+IF(4<=Assumptions!$B$40,D32,0)+IF(3<=Assumptions!$B$40,E32,0)+IF(2<=Assumptions!$B$40,F32,0)+IF(1<=Assumptions!$B$40,G32,0) -> 19385.207 | H33: =IF(7<=Assumptions!$B$40,B32,0)+IF(6<=Assumptions!$B$40,C32,0)+IF(5<=Assumptions!$B$40,D32,0)+IF(4<=Assumptions!$B$40,E32,0)+IF(3<=Assumptions!$B$40,F32,0)+IF(2<=Assumptions!$B$40,G32,0)+IF(1<=Assumptions!$B$40,H32,0) -> 40414.077 | I33: =IF(8<=Assumptions!$B$40,B32,0)+IF(7<=Assumptions!$B$40,C32,0)+IF(6<=Assumptions!$B$40,D32,0)+IF(5<=Assumptions!$B$40,E32,0)+IF(4<=Assumptions!$B$40,F32,0)+IF(3<=Assumptions!$B$40,G32,0)+IF(2<=Assumptions!$B$40,H32,0)+IF(1<=Assumptions!$B$40,I32,0) -> 40414.077 | J33: =IF(9<=Assumptions!$B$40,B32,0)+IF(8<=Assumptions!$B$40,C32,0)+IF(7<=Assumptions!$B$40,D32,0)+IF(6<=Assumptions!$B$40,E32,0)+IF(5<=Assumptions!$B$40,F32,0)+IF(4<=Assumptions!$B$40,G32,0)+IF(3<=Assumptions!$B$40,H32,0)+IF(2<=Assumptions!$B$40,I32,0)+IF(1<=Assumptions!$B$40,J32,0) -> 21028.87 | K33: =IF(10<=Assumptions!$B$40,B32,0)+IF(9<=Assumptions!$B$40,C32,0)+IF(8<=Assumptions!$B$40,D32,0)+IF(7<=Assumptions!$B$40,E32,0)+IF(6<=Assumptions!$B$40,F32,0)+IF(5<=Assumptions!$B$40,G32,0)+IF(4<=Assumptions!$B$40,H32,0)+IF(3<=Assumptions!$B$40,I32,0)+IF(2<=Assumptions!$B$40,J32,0)+IF(1<=Assumptions!$B$40,K32,0) -> 21028.87 | M33: Every loan still inside its term. Drops off as each set is paid down - which is the moment the company starts throwing off real cash.
A34: Debt service on the start-up loans (Kiva, microloan, family note) | B34: ='Startup budget and funding'!B$40 -> 15288.505 | C34: ='Startup budget and funding'!C$40 -> 15288.505 | D34: ='Startup budget and funding'!D$40 -> 15288.505 | E34: ='Startup budget and funding'!E$40 -> 10288.505 | F34: ='Startup budget and funding'!F$40 -> 10288.505 | G34: ='Startup budget and funding'!G$40 -> 7968.5683 | H34: ='Startup budget and funding'!H$40 -> 7968.5683 | I34: ='Startup budget and funding'!I$40 -> 0 | ... K34: ='Startup budget and funding'!K$40 -> 0 | M34: From the funding tab - the loans that got you open, separate from the equipment.
A35: CASH - THE NUMBER THAT DECIDES WHETHER YOU ARE STILL HERE
A36: Estimated income tax (on profit after depreciation) | B36: =MAX(0,B27-B30/Assumptions!$B$41)*Assumptions!$B$43 -> 0 | C36: =MAX(0,C27-C30/Assumptions!$B$41)*Assumptions!$B$43 -> 15646.969 | D36: =MAX(0,D27-D30/Assumptions!$B$41)*Assumptions!$B$43 -> 29318.202 | E36: =MAX(0,E27-E30/Assumptions!$B$41)*Assumptions!$B$43 -> 42616.731 | F36: =MAX(0,F27-F30/Assumptions!$B$41)*Assumptions!$B$43 -> 47684.341 | G36: =MAX(0,G27-G30/Assumptions!$B$41)*Assumptions!$B$43 -> 47438.621 | H36: =MAX(0,H27-H30/Assumptions!$B$41)*Assumptions!$B$43 -> 81961.811 | I36: =MAX(0,I27-I30/Assumptions!$B$41)*Assumptions!$B$43 -> 88028.781 | ... K36: =MAX(0,K27-K30/Assumptions!$B$41)*Assumptions!$B$43 -> 88480.167 | M36: Rough. Your salary is already deducted above; this is the tax on what the company itself makes. Section 179 could take the whole equipment cost in year one instead - the CPA decides. The Owner pay tab covers the tax on your own salary.
A37: CASH GENERATED THIS YEAR | B37: =B27-B31-B33-B34-B36 -> -24133.561 | C37: =C27-C31-C33-C34-C36 -> 3351.0742 | D37: =D27-D31-D33-D34-D36 -> 35250.617 | E37: =E27-E31-E33-E34-E36 -> 51895.31 | F37: =F27-F31-F33-F34-F36 -> 63719.735 | G37: =G27-G31-G33-G34-G36 -> 83336.341 | H37: =H27-H31-H33-H34-H36 -> 142861.58 | I37: =I27-I31-I33-I34-I36 -> 164986.41 | ... K37: =K27-K31-K33-K34-K36 -> 185424.85
A38: Cash at the start of the year | B38: ='Startup budget and funding'!B44 -> 77800 | C38: =B39 -> 53666.439 | D38: =C39 -> 57017.513 | E38: =D39 -> 92268.131 | F38: =E39 -> 144163.44 | G38: =F39 -> 207883.17 | H38: =G39 -> 291219.52 | I38: =H39 -> 434081.09 | J38: =I39 -> 599067.51 | K38: =J39 -> 784125.98 | M38: Year 1 opens with whatever the funding tab leaves over after the equipment and the start-up costs.
A39: CASH AT YEAR END | B39: =B38+B37 -> 53666.439 | C39: =C38+C37 -> 57017.513 | D39: =D38+D37 -> 92268.131 | E39: =E38+E37 -> 144163.44 | F39: =F38+F37 -> 207883.17 | G39: =G38+G37 -> 291219.52 | H39: =H38+H37 -> 434081.09 | I39: =I38+I37 -> 599067.51 | ... K39: =K38+K37 -> 969550.83 | M39: If this goes negative the company is dead, whatever the profit line says. Fix it by starting with more working capital, pricing higher, or adding the second crew later - in that order.
A40: Solvent? | B40: =IF(B39>=0,"yes","NO - OUT OF CASH") -> yes | C40: =IF(C39>=0,"yes","NO - OUT OF CASH") -> yes | D40: =IF(D39>=0,"yes","NO - OUT OF CASH") -> yes | E40: =IF(E39>=0,"yes","NO - OUT OF CASH") -> yes | F40: =IF(F39>=0,"yes","NO - OUT OF CASH") -> yes | G40: =IF(G39>=0,"yes","NO - OUT OF CASH") -> yes | H40: =IF(H39>=0,"yes","NO - OUT OF CASH") -> yes | I40: =IF(I39>=0,"yes","NO - OUT OF CASH") -> yes | ... K40: =IF(K39>=0,"yes","NO - OUT OF CASH") -> yes
A41: WHAT YOU ACTUALLY TAKE HOME FROM THE COMPANY
A42: Owner's cash (your salary + operating profit) - what a buyer calls SDE | B42: =B25+B27 -> 64024.96 | C42: =C25+C27 -> 111556.56 | D42: =D25+D27 -> 161879.34 | E42: =E25+E27 -> 228696.56 | F42: =F25+F27 -> 233774.7 | G42: =G25+G27 -> 238941.78 | H42: =H25+H27 -> 379312.42 | I42: =I25+I27 -> 387689.61 | ... K42: =K25+K27 -> 404879.14 | M42: This is the number the company is valued on, and it is the honest measure of what it pays you versus a job. Compare it to the foreman wage on the ladder in your other file.
...

Sheet Startup budget and funding
A1: What it costs to open the doors, and where every dollar comes from
A2: Blue = change it. Uses on the left must be covered by sources - the gap line tells you if they are not.
A4: USES - WHAT YOU HAVE TO PAY FOR
A5: First equipment set (from Assumptions) | B5: =Assumptions!$B$37 -> 80000 | F5: Used mini-ex, used track loader, trailer, tools. About $80K used.
A6: Insurance deposit and first instalments | B6: 5000 | F6: Carriers want a down payment on a new account.
A7: LLC, EIN, LSLBC registration, exam, first-year licences | B7: 1200 | F7: Louisiana Home Improvement registration covers jobs from $7,500 to $50,000; the Residential licence (needed above $50,000 a job) requires $50,000 net worth. Registration is enough to open.
A8: Working capital - three months of overhead and payroll before the money comes in | B8: 22000 | F8: The single most under-budgeted line in every failed contractor's story. Do not cut it.
A9: Reserve for the first thing that breaks | B9: 5000 | F9: Something will.
A10: TOTAL USES | B10: =SUM(B5:B9) -> 113200
A12: SOURCES - WHERE IT COMES FROM
A13: Source | B13: Amount | C13: Rate (APR) | D13: Years | E13: Payment / yr | F13: What it is and whether you can actually get it
A14: Your own savings (from Assumptions) | B14: =Assumptions!$B$6 -> 35000 | C14: 0 | D14: 0 | E14: =IF(OR(D14=0,B14=0),0,IF(C14=0,B14/D14,PMT(C14/12,D14*12,-B14)*12)) -> 0 | F14: Your equity injection. Every lender below wants to see it. Around 10-20% of the total is what they expect.
A15: Kiva US - 0% crowdfunded loan | B15: 15000 | C15: 0 | D15: 3 | E15: =IF(OR(D15=0,B15=0),0,IF(C15=0,B15/D15,PMT(C15/12,D15*12,-B15)*12)) -> 5000 | F15: Up to $15,000 at 0%, no minimum credit score, age 18+. You have to recruit 5-40 people from your own network to lend first - which is exactly the relationship test this whole plan is about. Realistic on day one.
A16: SBA / Louisiana SSBCI microloan | B16: 40000 | C16: 0.1 | D16: 7 | E16: =IF(OR(D16=0,B16=0),0,IF(C16=0,B16/D16,PMT(C16/12,D16*12,-B16)*12)) -> 7968.5683 | F16: Up to $50,000, 8-13%, up to 7 years; a quarter of these go to businesses under two years old. Louisiana microlenders: TruFund, JEDCO, NewCorp, Carter and Essential credit unions. Realistic with a 620+ score, collateral and a personal guarantee.
A17: Equipment loan on the first set (computed from Assumptions) | B17: =Assumptions!$B$37*(1-Assumptions!$B$38) -> 64000 | C17: =Assumptions!$B$39 -> 0.14 | D17: =Assumptions!$B$40 -> 5 | E17: =IF(OR(D17=0,B17=0),0,IF(C17=0,B17/D17,PMT(C17/12,D17*12,-B17)*12)) -> 17870.017 | F17: An independent equipment lender - no time-in-business minimum, but 680-700+ personal credit, 10-25% down and documented operator experience. This is why the credit you build from 18 matters. Dealer 0% promotions are usually new equipment only.
A18: Family note (written, at a fair rate, subordinated to the lenders above) | B18: 10000 | C18: 0.06 | D18: 5 | E18: =IF(OR(D18=0,B18=0),0,IF(C18=0,B18/D18,PMT(C18/12,D18*12,-B18)*12)) -> 2319.9362 | F18: If family helps, do it properly: a written promissory note at or above the IRS applicable federal rate (mid-term AFR is about 4.5% in September 2026), 5 years, and ranked behind the bank. A gift under $19,000 a year needs no paperwork at all - but a loan does.
A19: TOTAL SOURCES | B19: =SUM(B14:B18) -> 164000
A20: GAP - sources minus uses (must be zero or better) | B20: =B19-B10 -> 50800 | F20: Positive is extra cushion and flows into opening cash below. Negative means you cannot open yet - raise savings, take a smaller equipment set, or wait a year.
A38: START-UP LOAN PAYMENTS BY YEAR (Kiva, microloan, family note) - read by the proforma
A39: Year | B39: 1 | C39: 2 | D39: 3 | E39: 4 | F39: 5 | G39: 6 | H39: 7 | I39: 8 | J39: 9 | K39: 10
A40: Annual payments on the start-up loans | B40: =IF(1<=D15,E15,0)+IF(1<=D16,E16,0)+IF(1<=D18,E18,0) -> 15288.505 | C40: =IF(2<=D15,E15,0)+IF(2<=D16,E16,0)+IF(2<=D18,E18,0) -> 15288.505 | D40: =IF(3<=D15,E15,0)+IF(3<=D16,E16,0)+IF(3<=D18,E18,0) -> 15288.505 | E40: =IF(4<=D15,E15,0)+IF(4<=D16,E16,0)+IF(4<=D18,E18,0) -> 10288.505 | F40: =IF(5<=D15,E15,0)+IF(5<=D16,E16,0)+IF(5<=D18,E18,0) -> 10288.505 | G40: =IF(6<=D15,E15,0)+IF(6<=D16,E16,0)+IF(6<=D18,E18,0) -> 7968.5683 | H40: =IF(7<=D15,E15,0)+IF(7<=D16,E16,0)+IF(7<=D18,E18,0) -> 7968.5683 | I40: =IF(8<=D15,E15,0)+IF(8<=D16,E16,0)+IF(8<=D18,E18,0) -> 0 | J40: =IF(9<=D15,E15,0)+IF(9<=D16,E16,0)+IF(9<=D18,E18,0) -> 0 | K40: =IF(10<=D15,E15,0)+IF(10<=D16,E16,0)+IF(10<=D18,E18,0) -> 0
A44: OPENING CASH ON DAY ONE (working capital + reserve + any gap cushion) | B44: =B8+B9+MAX(0,B20) -> 77800 | F44: This is what the proforma starts with in the bank. The equipment, insurance and licences are already paid out of the sources above.

Sheet Loans and credit ladder
A1: Other people's money - what you can get, at what age, in what order
A2: The whole point of this tab is that you apply for the right thing at the right time and never collect a pile of declines. Declines cost you - each one is a hard inquiry. Verified September 2026; terms move, so re-check before applying.
A4: PART ONE - BUILDING THE CREDIT THAT MAKES THE LOANS POSSIBLE
A5: Age | B5: What you do | C5: What it gets you | D5: Why, and the trap to avoid
A6: 18 | B6: The week you turn 18: become an authorised user on Dad's oldest, cleanest card AND open your own secured card ($200-500 deposit). Same month. | C6: A credit file that starts aging immediately. First score after 6 months. | D6: The authorised-user account brings its whole payment history with it. Your own secured card is the one that proves YOU pay. Use it for fuel, pay it in full every month, never carry a balance. Utilisation under 10%.
A7: 18-19 | B7: A small credit-builder loan from a credit union ($500-1,000 over 12 months). | C7: An instalment tradeline alongside the card. | D7: Scores reward a mix. Cost is a few dollars of interest. Do NOT take a car loan to build credit - that is the classic mistake.
A8: 19 | B8: Apply for the M.J. Foster Promise ($3,200 a year, $6,400 lifetime) for a heavy-equipment or CDL credential. | C8: A free licence. | D8: Minimum age was lowered to 19 for 2026-27. Construction is an eligible field. Income limit is 300% of poverty or 'underemployed' - at $20/hr you qualify.
A9: 20 | B9: Graduate the secured card to unsecured; add one rewards card. Never more than two or three cards. | C9: About 700 by 21 if nothing was ever late. | D9: Age of file is the ceiling now, not behaviour. Do not churn new accounts - every application is a hard inquiry and a younger average age.
A10: 21-22 | B10: Form the LLC, get the EIN and a D-U-N-S number, open a business checking account. Then open net-30 accounts with vendors that actually report to business bureaus and buy small things through them. | C10: A business credit file that starts aging 2-3 years before you need it. | D10: Only about 2% of suppliers report at all. Verified in 2026: Uline (D&B and Experian), Quill (D&B and Experian), Crown Office Supplies (all three), Grainger (reports, will not say where). Form the LLC about 12 months before your first equipment application - tradelines only age from the date opened.
A11: 22 | B11: Bank of America Business Advantage Secured card ($1,000 deposit). | C11: A business card that reports to D&B and graduates to unsecured. | D11: The practical first business card. 26.74% APR is irrelevant if it is paid in full every month, which it will be.
A12: 22-24 | B12: Personal score 740+. Business file 2-3 years old. Two years of your own tax returns showing W-2 income. | C12: You are now what every lender on the list below is looking for. | D12: This is the whole reason the sequence starts at 18. A 24-year-old with a six-year clean file and a 740 score gets a 14% equipment loan. The same person with a two-year file gets 19% or a decline.
A14: PART TWO - THE LOANS, IN THE ORDER YOU CAN ACTUALLY GET THEM
A15: When | B15: Loan | C15: Terms (Sept 2026) | D15: Can you actually get it - the blunt answer
A16: Day one | B16: Kiva US | C16: $1,000-15,000, 0% interest, up to 3 years, up to 6 months grace. No credit-score minimum. | D16: YES. You must get 5-40 people from your own network to lend to you within 15 days before Kiva opens it to the public. That is a test of exactly the relationships this plan tells you to build. Tools and trailer money.
A17: Day one | B17: Business credit card with a personal guarantee (Amex Blue Business Cash, Chase Ink) | C17: New LLC with $0 revenue accepted on personal credit of roughly 690+. | D17: YES if your personal score is there - which is what Part One was for. Fuel and materials float, paid in full monthly. Never a financing tool.
A18: Day one | B18: SBA microloan / Louisiana SSBCI microloan | C18: Up to $50,000; 8-13%; up to 7 years; average loan about $15,400. 620+ score recommended; collateral and personal guarantee. | D18: YES - this is your first real loan. A quarter of these go to businesses under two years old. Louisiana lenders: TruFund, JEDCO, NewCorp, Carter Credit Union, Essential Credit Union.
A19: Day one | B19: Independent equipment lender - used mini-ex | C19: No time-in-business minimum; 680-700+ personal credit; 10-25% down; 13-18% APR for a new business, 3-8 points above an established one; used units capped at 10-15 years old. | D19: YES with a 700+ score, 20% down and years of documented operator time. Kubota Credit takes ~620+ with 10-15% down. Cat Financial wants a personal guarantee under 5 years. Dealer 0% promotions are almost always NEW equipment only.
A20: Day one | B20: Family note | C20: Written promissory note at or above the IRS applicable federal rate (about 4.5% mid-term, Sept 2026), typically 5 years, subordinated to the lenders above. | D20: YES if the family is willing - and it must be papered. Loans under $10,000 are exempt from imputed-interest rules; gifts under $19,000 a year need no paperwork. A handshake loan is a gift-tax problem and a family problem waiting to happen.
A21: Year 1-2 | B21: Louisiana SSBCI Small Business Loan Guaranty | C21: State guarantees up to 80% of a bank loan (up to $1.5M); fee 0-2%; 15% equity required; start-up costs eligible; must create 1 job per $100,000. | D21: MAYBE. The guaranty makes a $75-150K start-up deal bankable, but a Louisiana bank still has to originate it - and they will want a written letter from customers or the contractor you left. Worth walking into a local bank with, not counting on.
A22: Year 2-3 | B22: SBA 7(a) - Community Advantage through LiftFund | C22: Prime plus up to 6%; LiftFund explicitly serves start-ups and Louisiana; 10% equity injection for a business under a year old. | D22: NOT until you have two filed tax returns. Legally a start-up is eligible; practically, lenders decline without history. The October 2026 rule changes hit acquisitions, not start-ups - projections still count for a new business. This is your year-3 growth loan for crew 2.
A23: Year 3+ | B23: Bank line of credit | C23: Prime plus 1-3% for an established contractor; secured by receivables. | D23: NOT before two years of returns and a banker who has watched you. Start the relationship at 21 - see Part One.
A24: Never (for this) | B24: SBA 504 | C24: Up to $5.5M for equipment and real estate; equipment needs 10+ years of remaining life; no working capital. | D24: NO. Wrong size, and a used mini-excavator fails the ten-year-life test. If you ever buy a yard with a shop on it, revisit.
A25: At formation | B25: Hudson Initiative certification | C25: Free. Under 50 employees and $10M receipts. Adds 10% to your score on Louisiana state bids and waives the quote requirement under $25,000. | D25: YES, and it costs nothing. Certify the day the LLC exists.
A27: Read the colours: green is available to you at launch if you did Part One. Amber is real but needs history you will not have yet. Red is not for this. The realistic day-one stack is your savings + Kiva + a microloan + an equipment loan with 20% down + possibly a family note - which is exactly what the funding tab is built from.

Sheet Owner pay and write-offs
A1: What you actually keep - your salary after tax, and what the write-offs do to it
A2: Blue = change it. Year-1 figures. Every line is an estimate for planning - a CPA sets the real numbers, and the CPA is worth several times what he costs.
A4: YOUR SALARY, BEFORE ANYTHING
A5: Your salary in year 1 (from Assumptions) | B5: =Assumptions!$B$34 -> 55000 | C5: Set on the Assumptions tab. As a single-member LLC all the company's profit is taxed to you anyway - this is the part you actually pay yourself to live on.
A6: WRITE-OFFS - LEGAL, AND EXACTLY THE SAME LIST CHARLIE USES
A7: Business miles a year on your truck | B7: 12000 | C7: You are now the estimator AND the owner. Log every mile - an app is fine.
A8: IRS mileage rate ($/mile, 2026 blended) | B8: 0.743 | C8: 72.5 cents Jan-Jun 2026, 76 cents Jul-Dec. Covers fuel, tyres, repairs, insurance, depreciation - do not also deduct fuel for these miles.
A9: Vehicle deduction | B9: =B7*B8 -> 8916
A10: Section 179 - expense the first equipment set in year one instead of over five years | B10: =Assumptions!$B$37 -> 80000 | C10: 2026 Section 179 limit is $2.56M and bonus depreciation is 100% and permanent. A financed machine still qualifies - a $1-buyout lease or a straight loan counts, a fair-market-value lease does not. Whether to take it all in year one or spread it is a CPA question; the proforma tab spreads it to stay conservative.
A11: Home office (simplified: $5 a sq ft up to 300 sq ft) | B11: 1500 | C11: Only if a space is used regularly and exclusively for the business.
A12: Self-employed health insurance premiums | B12: 4800 | C12: Above the line. At 25 this is cheap - buy it, both because it is deductible and because you dig holes for a living.
A13: Solo 401(k) contribution (% of salary) | B13: 0.1 | C13: 2026 limits: $24,500 employee deferral plus profit-sharing, $72,000 combined. Ten percent from year one is the habit that matters more than the amount. Roth contributions can come back out tax-free if you ever need seed money for crew 2.
A14: Retirement deduction | B14: =B5*B13 -> 5500
A15: Phone, licences, dues, tools under $2,500, bank and card fees | B15: 3000 | C15: Small tools under $2,500 each can be expensed outright under the de minimis safe harbour.
A16: TOTAL WRITE-OFFS AGAINST YOUR OWN TAX | B16: =B9+B11+B12+B14+B15 -> 23716 | C16: Materials, wages, insurance and the equipment are already deducted inside the company's numbers on the proforma tab - not counted twice here.
A17: WHAT THAT IS WORTH
A18: Your combined marginal rate (federal + 15.3% self-employment + Louisiana 3%) | B18: 0.32 | C18: Blended. The QBI deduction (20% of qualified business income, now permanent) is on top of this and is why a CPA is worth it.
A19: Tax saved by the write-offs | B19: =B16*B18 -> 7589.12
A20: Estimated tax on your salary after write-offs | B20: =MAX(0,B5-B16+B14)*B18 -> 11770.88 | C20: The retirement money is added back because it is deferred, not spent - it is still yours.
A21: WHAT YOU ACTUALLY KEEP IN YEAR ONE (salary less tax, plus the retirement you put away) | B21: =B5-B20 -> 43229.12 | C21: Compare this to the take-home column on the ladder in your other file at the same age. In year one of your own company it is usually LESS. The difference is what you are paying for the equity you now own.
A22: THE S-CORP QUESTION - WHEN IT STARTS TO PAY
A23: Once the company clears about $60,000-80,000 of profit a year, electing S-corporation status lets you pay yourself a 'reasonable salary' and take the rest as a distribution that is not subject to the 15.3% self-employment tax. At $90,000 of profit with a $54,000 salary the net saving is about $3,400 a year after the extra $2,000-4,000 of payroll and compliance cost.
A24: Below that it is marginal or negative, because the compliance cost eats the saving. On the defaults in this file that means: do NOT elect in year one. Revisit in year two with the CPA, once the numbers are real. The IRS actively audits S-corps that pay an unreasonably low salary, so this is a decision to make with a professional and never on your own.

Sheet What it is worth
A1: What the company is worth, year by year - and the honest word on investors
A2: Formulas off the proforma and the SDE multiple on Assumptions. This is what a buyer would pay, not what you would ask.
A4: Year | B4: 1 | C4: 2 | D4: 3 | E4: 4 | F4: 5 | G4: 6 | H4: 7 | I4: 8 | J4: 9 | K4: 10
A5: Revenue | B5: ='Ten-year proforma'!B12 -> 290304 | C5: ='Ten-year proforma'!C12 -> 361307.52 | D5: ='Ten-year proforma'!D12 -> 436309.98 | E5: ='Ten-year proforma'!E12 -> 898798.55 | F5: ='Ten-year proforma'!F12 -> 925762.51 | G5: ='Ten-year proforma'!G12 -> 953535.39 | H5: ='Ten-year proforma'!H12 -> 1473212.2 | I5: ='Ten-year proforma'!I12 -> 1517408.5 | ... K5: ='Ten-year proforma'!K12 -> 1609818.7
A6: Owner's cash (SDE) | B6: ='Ten-year proforma'!B42 -> 64024.96 | C6: ='Ten-year proforma'!C42 -> 111556.56 | D6: ='Ten-year proforma'!D42 -> 161879.34 | E6: ='Ten-year proforma'!E42 -> 228696.56 | F6: ='Ten-year proforma'!F42 -> 233774.7 | G6: ='Ten-year proforma'!G42 -> 238941.78 | H6: ='Ten-year proforma'!H42 -> 379312.42 | I6: ='Ten-year proforma'!I42 -> 387689.61 | ... K6: ='Ten-year proforma'!K42 -> 404879.14
A7: Multiple a buyer pays | B7: =Assumptions!$B$44 -> 2.49 | C7: =Assumptions!$B$44 -> 2.49 | D7: =Assumptions!$B$44 -> 2.49 | E7: =Assumptions!$B$44 -> 2.49 | F7: =Assumptions!$B$44 -> 2.49 | G7: =Assumptions!$B$44 -> 2.49 | H7: =Assumptions!$B$44 -> 2.49 | I7: =Assumptions!$B$44 -> 2.49 | ... K7: =Assumptions!$B$44 -> 2.49 | M7: 2.49x SDE for a business under about $2M of revenue - the same BizBuySell figure the Scag Scapes model uses. Bigger companies earn bigger multiples because different buyers show up; on the defaults you stay in this band for ten years.
A8: Less debt still owed (equipment, rough) | B8: =-MAX(0,'Ten-year proforma'!B33*2.5) -> -44675.042 | C8: =-MAX(0,'Ten-year proforma'!C33*2.5) -> -44675.042 | D8: =-MAX(0,'Ten-year proforma'!D33*2.5) -> -44675.042 | E8: =-MAX(0,'Ten-year proforma'!E33*2.5) -> -93138.06 | F8: =-MAX(0,'Ten-year proforma'!F33*2.5) -> -93138.06 | G8: =-MAX(0,'Ten-year proforma'!G33*2.5) -> -48463.018 | H8: =-MAX(0,'Ten-year proforma'!H33*2.5) -> -101035.19 | I8: =-MAX(0,'Ten-year proforma'!I33*2.5) -> -101035.19 | ... K8: =-MAX(0,'Ten-year proforma'!K33*2.5) -> -52572.176 | M8: A rough estimate of remaining equipment principal - about two and a half years of payments at any point. A buyer pays for the business, then the debt comes out of your side.
A9: WHAT YOU COULD SELL IT FOR | B9: =MAX(0,B6)*B7+B8+'Ten-year proforma'!B39 -> 168413.55 | C9: =MAX(0,C6)*C7+C8+'Ten-year proforma'!C39 -> 290118.32 | D9: =MAX(0,D6)*D7+D8+'Ten-year proforma'!D39 -> 450672.65 | E9: =MAX(0,E6)*E7+E8+'Ten-year proforma'!E39 -> 620479.82 | F9: =MAX(0,F6)*F7+F8+'Ten-year proforma'!F39 -> 696844.11 | G9: =MAX(0,G6)*G7+G8+'Ten-year proforma'!G39 -> 837721.54 | H9: =MAX(0,H6)*H7+H8+'Ten-year proforma'!H39 -> 1277533.8 | I9: =MAX(0,I6)*I7+I8+'Ten-year proforma'!I39 -> 1463379.4 | ... K9: =MAX(0,K6)*K7+K8+'Ten-year proforma'!K39 -> 1925127.7 | M9: SDE times the multiple, minus debt, plus the cash in the bank. On the defaults, a three-crew company at year ten is worth more than the house most people your age are trying to buy - built from an $80K used equipment set and a secured credit card opened at 18.
A10: Cumulative owner's cash taken out along the way | B10: =B6 -> 64024.96 | C10: =B10+C6 -> 175581.52 | D10: =C10+D6 -> 337460.87 | E10: =D10+E6 -> 566157.43 | F10: =E10+F6 -> 799932.12 | G10: =F10+G6 -> 1038873.9 | H10: =G10+H6 -> 1418186.3 | I10: =H10+I6 -> 1805875.9 | J10: =I10+J6 -> 2202087.6 | K10: =J10+K6 -> 2606966.7
A11: EVERYTHING, IF YOU SOLD THAT YEAR | B11: =B10+B9 -> 232438.51 | C11: =C10+C9 -> 465699.84 | D11: =D10+D9 -> 788133.51 | E11: =E10+E9 -> 1186637.2 | F11: =F10+F9 -> 1496776.2 | G11: =G10+G9 -> 1876595.4 | H11: =H10+H9 -> 2695720.1 | I11: =I10+I9 -> 3269255.4 | ... K11: =K10+K9 -> 4532094.5 | M11: What you took out along the way plus what you would get for it. The honest total. Compare it to fifteen years of wages on the ladder in your other file.
A13: INVESTORS, PARTNERS, AND WHY YOU SHOULD SAY NO TO MOST OF THEM
A14: There is no outside investor for a one-crew excavation company, and there should not be. Institutional money does not exist at this size - confirmed against 2026 transaction data - and anyone offering you equity money for a start-up this small is either family or somebody you should be careful of. The right money is your savings, lenders who get repaid, and family on a written note.
A15: If somebody offers to buy the equipment in exchange for a share of the company - which happens, and is usually meant kindly - the answer is: thank you, and let's do it as a LEASE or a secured NOTE instead of equity. Their company (or they personally) owns the machine and rents it to yours at a fair rate, or lends you the money against it. They get paid first and get paid back. You keep 100% of the company, which matters more than it sounds: any owner of 20% or more has to personally guarantee every SBA loan you ever take, and a partner who did not want that is a partner you have just made unhappy.
A16: The family note, if there is one: a written promissory note, at or above the IRS applicable federal rate (about 4.5% for a mid-term loan in September 2026), five years, interest-only for the first six months if it helps, subordinated to any bank or SBA loan. Under $10,000 the IRS does not impute interest at all. Under $19,000 a year it can simply be a gift with no paperwork. But a loan gets a piece of paper, every time, because the paper is what keeps it from becoming a family argument.
A17: The one genuine 'investor' in this plan is Charlie. If at 25 the better move is a stake in Scag Scapes instead of your own company, this file is what tells you what your alternative is worth - and that is the only thing that lets you negotiate as an equal rather than as an employee being offered something.

Sheet Sources
A1: Where every number came from - verified September 2026
A3: Survival rates | B3: BLS Business Employment Dynamics, construction (NAICS 23): 1-year survival 79.7-83.2%, 2-year 71-75%, 5-year 62-64.5% for 2020-24 cohorts. https://www.bls.gov/bdm/us_age_naics_23_table7.txt
A4: Why contractors fail | B4: Cash flow and undercapitalisation, underbidding, no plan, growing too fast, people. https://www.constructconnect.com/blog/6-reasons-why-construction-companies-fail
A5: Louisiana french drain pricing | B5: $23-90 per linear foot; typical 75 LF job $1,688-6,750. https://costonce.com/costs/install-french-drain/louisiana
A6: Used equipment prices | B6: Bobcat E35 average asking $43,761, 2021-23 units $31.9-42.5K (machinerytrader.com). Bobcat T650 average $46,837, 2016-18 units $27-32K. 14,000 lb equipment trailer $6,190 new (kaufmantrailers.com).
A7: LSLBC licensing | B7: Home Improvement registration $7,500-$50,000; Residential licence above $50,000 or structural work, $50,000 net worth, GL of at least $100,000, workers' comp required. https://lslbc.gov/wp-content/uploads/2025/06/Licensing-Requirements-for-Contractors-in-Louisiana.pdf
A8: Insurance | B8: Excavation workers' comp class 6217 about $5.25 per $100 of payroll; Louisiana loss costs fell 5.3% May 2026 (NCCI). Small-excavator programme $12-35K/yr all-in. https://gritinsurance.com/blog/excavation-business-insurance-cost-2026
A9: SBA microloan | B9: Up to $50,000, 8-13%, up to 7 years, average $15,399; 26% of FY26 loans to businesses under 2 years. https://www.sba.gov/loans/microloans/ - Louisiana SSBCI microlenders: https://www.louisianassbci.com/programs/micro-lending/
A10: Kiva US | B10: $1,000-15,000 at 0%, no credit minimum, age 18+, 5-40 private lenders in 15 days. https://www.kiva.org/lp/faq-kiva-us-application-faqs
A11: Louisiana SSBCI loan guaranty | B11: Up to 80% guaranty, $1.5M cap, 0-2% fee, 15% equity, start-up costs eligible. https://www.louisianassbci.com/programs/small-business-loan-guaranty/
A12: SBA 7(a) for start-ups | B12: 10% equity injection under one year; SBSS score retired March 2026; DSCR 1.1x historical and/or projected; the October 2026 SOP changes affect acquisitions, not start-ups. https://www.naggl.org/wp-content/uploads/2026/05/5000-875701.pdf - LiftFund Community Advantage: https://www.liftfund.com/funding/our-products
A13: Equipment financing for a new business | B13: Independent lenders: no time-in-business minimum, 680+ credit, 10-25% down, 3-8 points above established rates. https://www.smarterfinanceusa.com/equipment-leasing-for-new-businesses - Kubota ~620+, 10-15% down. Tier-1 banks hold a hard 2-year rule.
A14: Credit building | B14: Authorised-user and secured-card sequence; first score after 6 months; Gen Z average FICO 678 (Sept 2025). https://www.experian.com/blogs/ask-experian/how-long-does-it-take-to-build-credit/ - Net-30 vendors verified to report (Aug 2026): Uline, Quill, Crown Office Supplies. https://companybaseos.com/blog/net-30-vendors-verified-list
... A20: Wages | B20: BLS OEWS May 2025, Baton Rouge: construction labourer median $18.58, equipment operator $27.99. East Baton Rouge specialty-trade wages grew 3.75%/yr 2019-2024 (QCEW).
