Workbook

Sheet Assumptions
A1: Scag Scapes LLC - Growth Proforma - Assumptions
A2: Blue = you can change it (yellow = the big levers). Black = formula, locked. Every tab recalculates from this one.
A4: OPERATIONS
A5: Average all-in revenue per linear foot ($/LF) | B5: 50 | C5: Charlie publishes $25-60/LF. $50 is the default because at 900 LF it reproduces Charlie's own rules of thumb: labor ~32% and ~50% margin.
A6: LF per month before Ned - today baseline (french drains only) | B6: 400 | C6: Where Charlie is right now, one crew. Used only to show the before/after - it does not drive the forward plan.
A7: Initial investment - next cash injection into the business ($) | B7: 25000 | C7: Funds launching two full crews together on day one instead of growing into a second crew over time: Crew 2's equipment down payment, hiring and the first months of marketing at full volume. Added to cash once, at the start of month 1. Change this to see what a bigger or smaller injection buys.
A8: Crew 1 - LF installed per month, month 1 | B8: 900 | C8: The plan starts with both crews already at Charlie's 800-1,000 LF/month goal - no ramp. Lower this to model easing in instead.
A9: Revenue per crew-day today ($) - Charlie | B9: 1500 | C9: Charlie: an average job day is about $1,500 of revenue now. The model reproduces this in month 1 (drain days + other-work days); shown as a check in the KPI rows.
A10: Working days per crew per month | B10: 21
A11: LF a crew installs per working day (productivity) | B11: 43 | C11: 900 LF / 21 days. At 400 LF/month a crew is only on drains ~9 days; the rest is other work. Growth = filling every day with drain feet.
A12: Other work revenue per crew-day when not on drains ($) - TODAY ONLY, before Ned | B12: 1000 | C12: Describes Charlie's situation right now, before French-drain volume fills every day - not part of the forward plan, which is drains only.
A13: Crew 1 - LF target per month (reached by month 6) | B13: 900 | C13: Charlie's stated goal (800-1,000).
A14: Crew 2 - start month (1-24) | B14: 1 | C14: Both crews launch together in month 1, funded by the initial investment above. Move this later to phase Crew 2 in instead.
A15: Crew 2 - LF per month, first month | B15: 900 | C15: Crew 2 also starts at target - no ramp, matching Crew 1.
A16: Crew 2 - LF target per month | B16: 900 | C16: Same productivity as Crew 1 once trained.
A17: Average job size (LF) | B17: 100 | C17: Demo average; a 100 LF job at $50/LF = $5,000 all-in.
A18: Backlog customers will wait (months of capacity) - demand beyond this is lost | B18: 1 | C18: A homeowner in a wet yard will wait about a month; past that they call the next company.
A19: COST STRUCTURE (share of install revenue)
A20: Labor cost method (1 = fixed 32% of revenue, 2 = crew wages x hours x burden) | B20: 2 | C20: 2 is the default: labor is what the crew is paid whether it installs 400 LF or 900 LF - that is why productivity is the margin lever. Set 1 to use Charlie's flat 32%.
A21: Direct labor % of revenue (used when method = 1) | B21: 0.32 | C21: Charlie: labor is roughly 32% of project cost.
A22: Materials + fuel % of revenue | B22: 0.2 | C22: Charlie: materials and gas roughly 20%.
A23: Crew wage - average $/hr | B23: 22.5 | C23: Charlie pays $20-25/hr. Change it and every month recalculates (method 2).
A24: Crew lead premium $/hr (added to one person per crew) | B24: 3 | C24: Lead earns $3/hr more than the laborers.
A25: Payroll burden % (taxes, WC, insurance) | B25: 0.14 | C25: Louisiana small-contractor burden estimate; replace with the actual workers' comp rate.
A26: Crew size (people) | B26: 3 | C26: Charlie.
A27: Paid hours per crew member per month | B27: 173 | C27: 40 h/wk x 52 / 12.
A28: Overtime hours per crew member per month | B28: 0 | C28: Paid at 1.5x. Set > 0 in busy months to see the effect.
A29: MAINTENANCE PLAN - 'DRAIN CHECK' (water-jet clean + flow test)
A30: Plan price per visit ($) | B30: 249 | C30: Angi 2026: hydro jetting $350-600 national average $475; priced under market because the crew knows the system it built.
A31: Plan close rate - customers who take a cleaning plan | B31: 0.6 | C31: Charlie's number: about 6 in 10 customers take a cleaning either yearly or every two years. Offered on every quote and again at the warranty walk.
A32: Share of plan customers on a 1-year cleaning (the rest are every 2 years) | B32: 0.5 | C32: Charlie: yearly or every 2 years. Move this and every plan number in the workbook moves.
A33: Cleaning visits per plan customer per year - computed | B33: =$B$32*1+(1-$B$32)*0.5 -> 0.75 | C33: Half on a yearly clean and half every two years averages 0.75 visits a year per customer. Not an input.
A34: Existing customers to offer the plan to (count) | B34: 150 | C34: Charlie to confirm; past installs are the first list.
A35: Existing-customer conversion in year 1 | B35: 0.15 | C35: Assumption; one text + one warranty-walk offer.
A36: Plan start month | B36: 3 | C36: Jetter already owned; needs a script, a price and a text template.
A37: Cost per maintenance visit ($) - 1 tech, 2 hrs, fuel, water | B37: 70 | C37: 1 person x 2 h x $22.50 x 1.18 burden + $17 fuel/consumables.
A38: LONG RANGE AND COMPANY VALUE
A39: Years to show on the long-range tab (1-15) | B39: 10 | C39: Change this to see 1 year or 15. The tab always computes 15; this is what gets summarised.
A40: Crews added per year after year 5 | B40: 0.5 | C40: Half a crew a year = one new crew every two years. The gates still apply: nothing is added until the last crew runs at target.
A41: Most crews one yard and one owner can run | B41: 8 | C41: Past this the answer is a second location or a general manager, which is a different plan.
...

Sheet Proforma 24 mo
A1: Scag Scapes LLC - 24-month operating proforma ($, monthly)
A2: All cells are formulas driven by the Assumptions tab. Month 1 = first month of the plan.
A4: Month | B4: 1 | C4: 2 | D4: 3 | E4: 4 | F4: 5 | G4: 6 | H4: 7 | I4: 8 | J4: 9 | K4: 10 | L4: 11 | M4: 12 | N4: 13 | O4: 14 | P4: 15 | Q4: 16 | R4: 17 | S4: 18 | T4: 19 | U4: 20 | V4: 21 | W4: 22 | X4: 23 | Y4: 24 | Z4: Year 1 | AA4: Year 2 | AB4: 24-mo total
A5: CAPACITY (linear feet installed)
A6: Crew 1 - LF/month | B6: =MIN(Assumptions!$B$13,Assumptions!$B$8+(Assumptions!$B$13-Assumptions!$B$8)*(1-1)/5) -> 900 | C6: =MIN(Assumptions!$B$13,Assumptions!$B$8+(Assumptions!$B$13-Assumptions!$B$8)*(2-1)/5) -> 900 | D6: =MIN(Assumptions!$B$13,Assumptions!$B$8+(Assumptions!$B$13-Assumptions!$B$8)*(3-1)/5) -> 900 | E6: =MIN(Assumptions!$B$13,Assumptions!$B$8+(Assumptions!$B$13-Assumptions!$B$8)*(4-1)/5) -> 900 | F6: =MIN(Assumptions!$B$13,Assumptions!$B$8+(Assumptions!$B$13-Assumptions!$B$8)*(5-1)/5) -> 900 | G6: =MIN(Assumptions!$B$13,Assumptions!$B$8+(Assumptions!$B$13-Assumptions!$B$8)*(6-1)/5) -> 900 | H6: =MIN(Assumptions!$B$13,Assumptions!$B$8+(Assumptions!$B$13-Assumptions!$B$8)*(7-1)/5) -> 900 | I6: =MIN(Assumptions!$B$13,Assumptions!$B$8+(Assumptions!$B$13-Assumptions!$B$8)*(8-1)/5) -> 900 | J6: =MIN(Assumptions!$B$13,Assumptions!$B$8+(Assumptions!$B$13-Assumptions!$B$8)*(9-1)/5) -> 900 | K6: =MIN(Assumptions!$B$13,Assumptions!$B$8+(Assumptions!$B$13-Assumptions!$B$8)*(10-1)/5) -> 900 | L6: =MIN(Assumptions!$B$13,Assumptions!$B$8+(Assumptions!$B$13-Assumptions!$B$8)*(11-1)/5) -> 900 | M6: =MIN(Assumptions!$B$13,Assumptions!$B$8+(Assumptions!$B$13-Assumptions!$B$8)*(12-1)/5) -> 900 | N6: =MIN(Assumptions!$B$13,Assumptions!$B$8+(Assumptions!$B$13-Assumptions!$B$8)*(13-1)/5) -> 900 | O6: =MIN(Assumptions!$B$13,Assumptions!$B$8+(Assumptions!$B$13-Assumptions!$B$8)*(14-1)/5) -> 900 | P6: =MIN(Assumptions!$B$13,Assumptions!$B$8+(Assumptions!$B$13-Assumptions!$B$8)*(15-1)/5) -> 900 | Q6: =MIN(Assumptions!$B$13,Assumptions!$B$8+(Assumptions!$B$13-Assumptions!$B$8)*(16-1)/5) -> 900 | R6: =MIN(Assumptions!$B$13,Assumptions!$B$8+(Assumptions!$B$13-Assumptions!$B$8)*(17-1)/5) -> 900 | S6: =MIN(Assumptions!$B$13,Assumptions!$B$8+(Assumptions!$B$13-Assumptions!$B$8)*(18-1)/5) -> 900 | T6: =MIN(Assumptions!$B$13,Assumptions!$B$8+(Assumptions!$B$13-Assumptions!$B$8)*(19-1)/5) -> 900 | U6: =MIN(Assumptions!$B$13,Assumptions!$B$8+(Assumptions!$B$13-Assumptions!$B$8)*(20-1)/5) -> 900 | V6: =MIN(Assumptions!$B$13,Assumptions!$B$8+(Assumptions!$B$13-Assumptions!$B$8)*(21-1)/5) -> 900 | W6: =MIN(Assumptions!$B$13,Assumptions!$B$8+(Assumptions!$B$13-Assumptions!$B$8)*(22-1)/5) -> 900 | X6: =MIN(Assumptions!$B$13,Assumptions!$B$8+(Assumptions!$B$13-Assumptions!$B$8)*(23-1)/5) -> 900 | Y6: =MIN(Assumptions!$B$13,Assumptions!$B$8+(Assumptions!$B$13-Assumptions!$B$8)*(24-1)/5) -> 900 | Z6: =SUM(B6:M6) -> 10800 | AA6: =SUM(N6:Y6) -> 10800 | AB6: =SUM(B6:Y6) -> 21600
A7: Crew 2 - LF/month | B7: =IF(1<Assumptions!$B$14,0,MIN(Assumptions!$B$16,Assumptions!$B$15+(Assumptions!$B$16-Assumptions!$B$15)*(1-Assumptions!$B$14)/3)) -> 900 | C7: =IF(2<Assumptions!$B$14,0,MIN(Assumptions!$B$16,Assumptions!$B$15+(Assumptions!$B$16-Assumptions!$B$15)*(2-Assumptions!$B$14)/3)) -> 900 | D7: =IF(3<Assumptions!$B$14,0,MIN(Assumptions!$B$16,Assumptions!$B$15+(Assumptions!$B$16-Assumptions!$B$15)*(3-Assumptions!$B$14)/3)) -> 900 | E7: =IF(4<Assumptions!$B$14,0,MIN(Assumptions!$B$16,Assumptions!$B$15+(Assumptions!$B$16-Assumptions!$B$15)*(4-Assumptions!$B$14)/3)) -> 900 | F7: =IF(5<Assumptions!$B$14,0,MIN(Assumptions!$B$16,Assumptions!$B$15+(Assumptions!$B$16-Assumptions!$B$15)*(5-Assumptions!$B$14)/3)) -> 900 | G7: =IF(6<Assumptions!$B$14,0,MIN(Assumptions!$B$16,Assumptions!$B$15+(Assumptions!$B$16-Assumptions!$B$15)*(6-Assumptions!$B$14)/3)) -> 900 | H7: =IF(7<Assumptions!$B$14,0,MIN(Assumptions!$B$16,Assumptions!$B$15+(Assumptions!$B$16-Assumptions!$B$15)*(7-Assumptions!$B$14)/3)) -> 900 | I7: =IF(8<Assumptions!$B$14,0,MIN(Assumptions!$B$16,Assumptions!$B$15+(Assumptions!$B$16-Assumptions!$B$15)*(8-Assumptions!$B$14)/3)) -> 900 | J7: =IF(9<Assumptions!$B$14,0,MIN(Assumptions!$B$16,Assumptions!$B$15+(Assumptions!$B$16-Assumptions!$B$15)*(9-Assumptions!$B$14)/3)) -> 900 | K7: =IF(10<Assumptions!$B$14,0,MIN(Assumptions!$B$16,Assumptions!$B$15+(Assumptions!$B$16-Assumptions!$B$15)*(10-Assumptions!$B$14)/3)) -> 900 | L7: =IF(11<Assumptions!$B$14,0,MIN(Assumptions!$B$16,Assumptions!$B$15+(Assumptions!$B$16-Assumptions!$B$15)*(11-Assumptions!$B$14)/3)) -> 900 | M7: =IF(12<Assumptions!$B$14,0,MIN(Assumptions!$B$16,Assumptions!$B$15+(Assumptions!$B$16-Assumptions!$B$15)*(12-Assumptions!$B$14)/3)) -> 900 | N7: =IF(13<Assumptions!$B$14,0,MIN(Assumptions!$B$16,Assumptions!$B$15+(Assumptions!$B$16-Assumptions!$B$15)*(13-Assumptions!$B$14)/3)) -> 900 | O7: =IF(14<Assumptions!$B$14,0,MIN(Assumptions!$B$16,Assumptions!$B$15+(Assumptions!$B$16-Assumptions!$B$15)*(14-Assumptions!$B$14)/3)) -> 900 | P7: =IF(15<Assumptions!$B$14,0,MIN(Assumptions!$B$16,Assumptions!$B$15+(Assumptions!$B$16-Assumptions!$B$15)*(15-Assumptions!$B$14)/3)) -> 900 | Q7: =IF(16<Assumptions!$B$14,0,MIN(Assumptions!$B$16,Assumptions!$B$15+(Assumptions!$B$16-Assumptions!$B$15)*(16-Assumptions!$B$14)/3)) -> 900 | R7: =IF(17<Assumptions!$B$14,0,MIN(Assumptions!$B$16,Assumptions!$B$15+(Assumptions!$B$16-Assumptions!$B$15)*(17-Assumptions!$B$14)/3)) -> 900 | S7: =IF(18<Assumptions!$B$14,0,MIN(Assumptions!$B$16,Assumptions!$B$15+(Assumptions!$B$16-Assumptions!$B$15)*(18-Assumptions!$B$14)/3)) -> 900 | T7: =IF(19<Assumptions!$B$14,0,MIN(Assumptions!$B$16,Assumptions!$B$15+(Assumptions!$B$16-Assumptions!$B$15)*(19-Assumptions!$B$14)/3)) -> 900 | U7: =IF(20<Assumptions!$B$14,0,MIN(Assumptions!$B$16,Assumptions!$B$15+(Assumptions!$B$16-Assumptions!$B$15)*(20-Assumptions!$B$14)/3)) -> 900 | V7: =IF(21<Assumptions!$B$14,0,MIN(Assumptions!$B$16,Assumptions!$B$15+(Assumptions!$B$16-Assumptions!$B$15)*(21-Assumptions!$B$14)/3)) -> 900 | W7: =IF(22<Assumptions!$B$14,0,MIN(Assumptions!$B$16,Assumptions!$B$15+(Assumptions!$B$16-Assumptions!$B$15)*(22-Assumptions!$B$14)/3)) -> 900 | X7: =IF(23<Assumptions!$B$14,0,MIN(Assumptions!$B$16,Assumptions!$B$15+(Assumptions!$B$16-Assumptions!$B$15)*(23-Assumptions!$B$14)/3)) -> 900 | Y7: =IF(24<Assumptions!$B$14,0,MIN(Assumptions!$B$16,Assumptions!$B$15+(Assumptions!$B$16-Assumptions!$B$15)*(24-Assumptions!$B$14)/3)) -> 900 | Z7: =SUM(B7:M7) -> 10800 | AA7: =SUM(N7:Y7) -> 10800 | AB7: =SUM(B7:Y7) -> 21600
A8: Capacity - total LF/month | B8: =B6+B7 -> 1800 | C8: =C6+C7 -> 1800 | D8: =D6+D7 -> 1800 | E8: =E6+E7 -> 1800 | F8: =F6+F7 -> 1800 | G8: =G6+G7 -> 1800 | H8: =H6+H7 -> 1800 | I8: =I6+I7 -> 1800 | ... Y8: =Y6+Y7 -> 1800 | Z8: =SUM(B8:M8) -> 21600 | AA8: =SUM(N8:Y8) -> 21600 | AB8: =SUM(B8:Y8) -> 43200
A9: DEMAND (leads and jobs)
A10: Leads - Google LSA | B10: =Assumptions!$B$64*IF(1>=Assumptions!$B$14,Assumptions!$B$75,1)/Assumptions!$B$65 -> 24.40678 | C10: =Assumptions!$B$64*IF(2>=Assumptions!$B$14,Assumptions!$B$75,1)/Assumptions!$B$65 -> 24.40678 | D10: =Assumptions!$B$64*IF(3>=Assumptions!$B$14,Assumptions!$B$75,1)/Assumptions!$B$65 -> 24.40678 | E10: =Assumptions!$B$64*IF(4>=Assumptions!$B$14,Assumptions!$B$75,1)/Assumptions!$B$65 -> 24.40678 | F10: =Assumptions!$B$64*IF(5>=Assumptions!$B$14,Assumptions!$B$75,1)/Assumptions!$B$65 -> 24.40678 | G10: =Assumptions!$B$64*IF(6>=Assumptions!$B$14,Assumptions!$B$75,1)/Assumptions!$B$65 -> 24.40678 | H10: =Assumptions!$B$64*IF(7>=Assumptions!$B$14,Assumptions!$B$75,1)/Assumptions!$B$65 -> 24.40678 | I10: =Assumptions!$B$64*IF(8>=Assumptions!$B$14,Assumptions!$B$75,1)/Assumptions!$B$65 -> 24.40678 | J10: =Assumptions!$B$64*IF(9>=Assumptions!$B$14,Assumptions!$B$75,1)/Assumptions!$B$65 -> 24.40678 | K10: =Assumptions!$B$64*IF(10>=Assumptions!$B$14,Assumptions!$B$75,1)/Assumptions!$B$65 -> 24.40678 | L10: =Assumptions!$B$64*IF(11>=Assumptions!$B$14,Assumptions!$B$75,1)/Assumptions!$B$65 -> 24.40678 | M10: =Assumptions!$B$64*IF(12>=Assumptions!$B$14,Assumptions!$B$75,1)/Assumptions!$B$65 -> 24.40678 | N10: =Assumptions!$B$64*IF(13>=Assumptions!$B$14,Assumptions!$B$75,1)/Assumptions!$B$65 -> 24.40678 | O10: =Assumptions!$B$64*IF(14>=Assumptions!$B$14,Assumptions!$B$75,1)/Assumptions!$B$65 -> 24.40678 | P10: =Assumptions!$B$64*IF(15>=Assumptions!$B$14,Assumptions!$B$75,1)/Assumptions!$B$65 -> 24.40678 | Q10: =Assumptions!$B$64*IF(16>=Assumptions!$B$14,Assumptions!$B$75,1)/Assumptions!$B$65 -> 24.40678 | R10: =Assumptions!$B$64*IF(17>=Assumptions!$B$14,Assumptions!$B$75,1)/Assumptions!$B$65 -> 24.40678 | S10: =Assumptions!$B$64*IF(18>=Assumptions!$B$14,Assumptions!$B$75,1)/Assumptions!$B$65 -> 24.40678 | T10: =Assumptions!$B$64*IF(19>=Assumptions!$B$14,Assumptions!$B$75,1)/Assumptions!$B$65 -> 24.40678 | U10: =Assumptions!$B$64*IF(20>=Assumptions!$B$14,Assumptions!$B$75,1)/Assumptions!$B$65 -> 24.40678 | V10: =Assumptions!$B$64*IF(21>=Assumptions!$B$14,Assumptions!$B$75,1)/Assumptions!$B$65 -> 24.40678 | W10: =Assumptions!$B$64*IF(22>=Assumptions!$B$14,Assumptions!$B$75,1)/Assumptions!$B$65 -> 24.40678 | X10: =Assumptions!$B$64*IF(23>=Assumptions!$B$14,Assumptions!$B$75,1)/Assumptions!$B$65 -> 24.40678 | Y10: =Assumptions!$B$64*IF(24>=Assumptions!$B$14,Assumptions!$B$75,1)/Assumptions!$B$65 -> 24.40678 | Z10: =SUM(B10:M10) -> 292.88136 | AA10: =SUM(N10:Y10) -> 292.88136 | AB10: =SUM(B10:Y10) -> 585.76271
A11: Leads - Facebook / Instagram | B11: =IF(1>=2,Assumptions!$B$67*IF(1>=Assumptions!$B$14,Assumptions!$B$75,1)/Assumptions!$B$68,0) -> 0 | C11: =IF(2>=2,Assumptions!$B$67*IF(2>=Assumptions!$B$14,Assumptions!$B$75,1)/Assumptions!$B$68,0) -> 17.454545 | D11: =IF(3>=2,Assumptions!$B$67*IF(3>=Assumptions!$B$14,Assumptions!$B$75,1)/Assumptions!$B$68,0) -> 17.454545 | E11: =IF(4>=2,Assumptions!$B$67*IF(4>=Assumptions!$B$14,Assumptions!$B$75,1)/Assumptions!$B$68,0) -> 17.454545 | F11: =IF(5>=2,Assumptions!$B$67*IF(5>=Assumptions!$B$14,Assumptions!$B$75,1)/Assumptions!$B$68,0) -> 17.454545 | G11: =IF(6>=2,Assumptions!$B$67*IF(6>=Assumptions!$B$14,Assumptions!$B$75,1)/Assumptions!$B$68,0) -> 17.454545 | H11: =IF(7>=2,Assumptions!$B$67*IF(7>=Assumptions!$B$14,Assumptions!$B$75,1)/Assumptions!$B$68,0) -> 17.454545 | I11: =IF(8>=2,Assumptions!$B$67*IF(8>=Assumptions!$B$14,Assumptions!$B$75,1)/Assumptions!$B$68,0) -> 17.454545 | J11: =IF(9>=2,Assumptions!$B$67*IF(9>=Assumptions!$B$14,Assumptions!$B$75,1)/Assumptions!$B$68,0) -> 17.454545 | K11: =IF(10>=2,Assumptions!$B$67*IF(10>=Assumptions!$B$14,Assumptions!$B$75,1)/Assumptions!$B$68,0) -> 17.454545 | L11: =IF(11>=2,Assumptions!$B$67*IF(11>=Assumptions!$B$14,Assumptions!$B$75,1)/Assumptions!$B$68,0) -> 17.454545 | M11: =IF(12>=2,Assumptions!$B$67*IF(12>=Assumptions!$B$14,Assumptions!$B$75,1)/Assumptions!$B$68,0) -> 17.454545 | N11: =IF(13>=2,Assumptions!$B$67*IF(13>=Assumptions!$B$14,Assumptions!$B$75,1)/Assumptions!$B$68,0) -> 17.454545 | O11: =IF(14>=2,Assumptions!$B$67*IF(14>=Assumptions!$B$14,Assumptions!$B$75,1)/Assumptions!$B$68,0) -> 17.454545 | P11: =IF(15>=2,Assumptions!$B$67*IF(15>=Assumptions!$B$14,Assumptions!$B$75,1)/Assumptions!$B$68,0) -> 17.454545 | Q11: =IF(16>=2,Assumptions!$B$67*IF(16>=Assumptions!$B$14,Assumptions!$B$75,1)/Assumptions!$B$68,0) -> 17.454545 | R11: =IF(17>=2,Assumptions!$B$67*IF(17>=Assumptions!$B$14,Assumptions!$B$75,1)/Assumptions!$B$68,0) -> 17.454545 | S11: =IF(18>=2,Assumptions!$B$67*IF(18>=Assumptions!$B$14,Assumptions!$B$75,1)/Assumptions!$B$68,0) -> 17.454545 | T11: =IF(19>=2,Assumptions!$B$67*IF(19>=Assumptions!$B$14,Assumptions!$B$75,1)/Assumptions!$B$68,0) -> 17.454545 | U11: =IF(20>=2,Assumptions!$B$67*IF(20>=Assumptions!$B$14,Assumptions!$B$75,1)/Assumptions!$B$68,0) -> 17.454545 | V11: =IF(21>=2,Assumptions!$B$67*IF(21>=Assumptions!$B$14,Assumptions!$B$75,1)/Assumptions!$B$68,0) -> 17.454545 | W11: =IF(22>=2,Assumptions!$B$67*IF(22>=Assumptions!$B$14,Assumptions!$B$75,1)/Assumptions!$B$68,0) -> 17.454545 | X11: =IF(23>=2,Assumptions!$B$67*IF(23>=Assumptions!$B$14,Assumptions!$B$75,1)/Assumptions!$B$68,0) -> 17.454545 | Y11: =IF(24>=2,Assumptions!$B$67*IF(24>=Assumptions!$B$14,Assumptions!$B$75,1)/Assumptions!$B$68,0) -> 17.454545 | Z11: =SUM(B11:M11) -> 192 | AA11: =SUM(N11:Y11) -> 209.45455 | AB11: =SUM(B11:Y11) -> 401.45455
A12: Leads - organic, referral, reviews, rain trigger | B12: =Assumptions!$B$70*(1+Assumptions!$B$71)^(1-1) -> 6 | C12: =Assumptions!$B$70*(1+Assumptions!$B$71)^(2-1) -> 6.36 | D12: =Assumptions!$B$70*(1+Assumptions!$B$71)^(3-1) -> 6.7416 | E12: =Assumptions!$B$70*(1+Assumptions!$B$71)^(4-1) -> 7.146096 | F12: =Assumptions!$B$70*(1+Assumptions!$B$71)^(5-1) -> 7.5748618 | G12: =Assumptions!$B$70*(1+Assumptions!$B$71)^(6-1) -> 8.0293535 | H12: =Assumptions!$B$70*(1+Assumptions!$B$71)^(7-1) -> 8.5111147 | I12: =Assumptions!$B$70*(1+Assumptions!$B$71)^(8-1) -> 9.0217816 | J12: =Assumptions!$B$70*(1+Assumptions!$B$71)^(9-1) -> 9.5630884 | K12: =Assumptions!$B$70*(1+Assumptions!$B$71)^(10-1) -> 10.136874 | L12: =Assumptions!$B$70*(1+Assumptions!$B$71)^(11-1) -> 10.745086 | M12: =Assumptions!$B$70*(1+Assumptions!$B$71)^(12-1) -> 11.389791 | N12: =Assumptions!$B$70*(1+Assumptions!$B$71)^(13-1) -> 12.073179 | O12: =Assumptions!$B$70*(1+Assumptions!$B$71)^(14-1) -> 12.79757 | P12: =Assumptions!$B$70*(1+Assumptions!$B$71)^(15-1) -> 13.565424 | Q12: =Assumptions!$B$70*(1+Assumptions!$B$71)^(16-1) -> 14.379349 | R12: =Assumptions!$B$70*(1+Assumptions!$B$71)^(17-1) -> 15.24211 | S12: =Assumptions!$B$70*(1+Assumptions!$B$71)^(18-1) -> 16.156637 | T12: =Assumptions!$B$70*(1+Assumptions!$B$71)^(19-1) -> 17.126035 | U12: =Assumptions!$B$70*(1+Assumptions!$B$71)^(20-1) -> 18.153597 | V12: =Assumptions!$B$70*(1+Assumptions!$B$71)^(21-1) -> 19.242813 | W12: =Assumptions!$B$70*(1+Assumptions!$B$71)^(22-1) -> 20.397382 | X12: =Assumptions!$B$70*(1+Assumptions!$B$71)^(23-1) -> 21.621224 | Y12: =Assumptions!$B$70*(1+Assumptions!$B$71)^(24-1) -> 22.918498 | Z12: =SUM(B12:M12) -> 101.21965 | AA12: =SUM(N12:Y12) -> 203.67382 | AB12: =SUM(B12:Y12) -> 304.89346
A13: Total leads | B13: =B10+B11+B12 -> 30.40678 | C13: =C10+C11+C12 -> 48.221325 | D13: =D10+D11+D12 -> 48.602925 | E13: =E10+E11+E12 -> 49.007421 | F13: =F10+F11+F12 -> 49.436187 | G13: =G10+G11+G12 -> 49.890679 | H13: =H10+H11+H12 -> 50.37244 | I13: =I10+I11+I12 -> 50.883107 | ... Y13: =Y10+Y11+Y12 -> 64.779823 | Z13: =SUM(B13:M13) -> 586.101 | AA13: =SUM(N13:Y13) -> 706.00972 | AB13: =SUM(B13:Y13) -> 1292.1107
A14: Estimate visits booked (leads x booking rate by channel) | B14: =B10*Assumptions!$B$66+B11*Assumptions!$B$69+B12*Assumptions!$B$72 -> 16.10339 | C14: =C10*Assumptions!$B$66+C11*Assumptions!$B$69+C12*Assumptions!$B$72 -> 21.573753 | D14: =D10*Assumptions!$B$66+D11*Assumptions!$B$69+D12*Assumptions!$B$72 -> 21.821793 | E14: =E10*Assumptions!$B$66+E11*Assumptions!$B$69+E12*Assumptions!$B$72 -> 22.084716 | F14: =F10*Assumptions!$B$66+F11*Assumptions!$B$69+F12*Assumptions!$B$72 -> 22.363414 | G14: =G10*Assumptions!$B$66+G11*Assumptions!$B$69+G12*Assumptions!$B$72 -> 22.658833 | H14: =H10*Assumptions!$B$66+H11*Assumptions!$B$69+H12*Assumptions!$B$72 -> 22.971978 | I14: =I10*Assumptions!$B$66+I11*Assumptions!$B$69+I12*Assumptions!$B$72 -> 23.303911 | ... Y14: =Y10*Assumptions!$B$66+Y11*Assumptions!$B$69+Y12*Assumptions!$B$72 -> 32.336777 | Z14: =SUM(B14:M14) -> 269.83345 | AA14: =SUM(N14:Y14) -> 341.66502 | AB14: =SUM(B14:Y14) -> 611.49847
A15: Jobs sold (estimates x Charlie's close rate) | B15: =B14*Assumptions!$B$74 -> 11.272373 | C15: =C14*Assumptions!$B$74 -> 15.101627 | D15: =D14*Assumptions!$B$74 -> 15.275255 | E15: =E14*Assumptions!$B$74 -> 15.459301 | F15: =F14*Assumptions!$B$74 -> 15.65439 | G15: =G14*Assumptions!$B$74 -> 15.861183 | H15: =H14*Assumptions!$B$74 -> 16.080385 | I15: =I14*Assumptions!$B$74 -> 16.312738 | ... Y15: =Y14*Assumptions!$B$74 -> 22.635744 | Z15: =SUM(B15:M15) -> 188.88341 | AA15: =SUM(N15:Y15) -> 239.16552 | AB15: =SUM(B15:Y15) -> 428.04893
A16: LF demanded (jobs x average job LF) | B16: =B15*Assumptions!$B$17 -> 1127.2373 | C16: =C15*Assumptions!$B$17 -> 1510.1627 | D16: =D15*Assumptions!$B$17 -> 1527.5255 | E16: =E15*Assumptions!$B$17 -> 1545.9301 | F16: =F15*Assumptions!$B$17 -> 1565.439 | G16: =G15*Assumptions!$B$17 -> 1586.1183 | H16: =H15*Assumptions!$B$17 -> 1608.0385 | I16: =I15*Assumptions!$B$17 -> 1631.2738 | ... Y16: =Y15*Assumptions!$B$17 -> 2263.5744 | Z16: =SUM(B16:M16) -> 18888.341 | AA16: =SUM(N16:Y16) -> 23916.552 | AB16: =SUM(B16:Y16) -> 42804.893
A17: LF installed (lesser of demand + backlog, capacity) | B17: =MIN(B16+0,B8) -> 1127.2373 | C17: =MIN(C16+B18,C8) -> 1510.1627 | D17: =MIN(D16+C18,D8) -> 1527.5255 | E17: =MIN(E16+D18,E8) -> 1545.9301 | F17: =MIN(F16+E18,F8) -> 1565.439 | G17: =MIN(G16+F18,G8) -> 1586.1183 | H17: =MIN(H16+G18,H8) -> 1608.0385 | I17: =MIN(I16+H18,I8) -> 1631.2738 | J17: =MIN(J16+I18,J8) -> 1655.9033 | ... Y17: =MIN(Y16+X18,Y8) -> 1800 | Z17: =SUM(B17:M17) -> 18888.341 | AA17: =SUM(N17:Y17) -> 21570.112 | AB17: =SUM(B17:Y17) -> 40458.454
A18: Backlog carried to next month (LF, capped; excess is lost demand) | B18: =MIN(B8*Assumptions!$B$18,MAX(0,B16+0-B17)) -> 0 | C18: =MIN(C8*Assumptions!$B$18,MAX(0,C16+B18-C17)) -> 0 | D18: =MIN(D8*Assumptions!$B$18,MAX(0,D16+C18-D17)) -> 0 | E18: =MIN(E8*Assumptions!$B$18,MAX(0,E16+D18-E17)) -> 0 | F18: =MIN(F8*Assumptions!$B$18,MAX(0,F16+E18-F17)) -> 0 | G18: =MIN(G8*Assumptions!$B$18,MAX(0,G16+F18-G17)) -> 0 | H18: =MIN(H8*Assumptions!$B$18,MAX(0,H16+G18-H17)) -> 0 | I18: =MIN(I8*Assumptions!$B$18,MAX(0,I16+H18-I17)) -> 0 | J18: =MIN(J8*Assumptions!$B$18,MAX(0,J16+I18-J17)) -> 0 | ... Y18: =MIN(Y8*Assumptions!$B$18,MAX(0,Y16+X18-Y17)) -> 1800
A19: Crew utilization | B19: =IF(B8=0,0,B17/B8) -> 0.62624294 | C19: =IF(C8=0,0,C17/C8) -> 0.8389793 | D19: =IF(D8=0,0,D17/D8) -> 0.8486253 | E19: =IF(E8=0,0,E17/E8) -> 0.85885006 | F19: =IF(F8=0,0,F17/F8) -> 0.86968831 | G19: =IF(G8=0,0,G17/G8) -> 0.88117685 | H19: =IF(H8=0,0,H17/H8) -> 0.8933547 | I19: =IF(I8=0,0,I17/I8) -> 0.90626322 | ... Y19: =IF(Y8=0,0,Y17/Y8) -> 1
A20: REVENUE
A21: Crew-days on drains (LF / LF per day) | B21: =B17/Assumptions!$B$11 -> 26.214821 | C21: =C17/Assumptions!$B$11 -> 35.120064 | D21: =D17/Assumptions!$B$11 -> 35.52385 | E21: =E17/Assumptions!$B$11 -> 35.951863 | F21: =F17/Assumptions!$B$11 -> 36.405557 | G21: =G17/Assumptions!$B$11 -> 36.886473 | H21: =H17/Assumptions!$B$11 -> 37.396243 | I21: =I17/Assumptions!$B$11 -> 37.9366 | ... Y21: =Y17/Assumptions!$B$11 -> 41.860465
A22: Drainage revenue (LF installed x $/LF) | B22: =B17*Assumptions!$B$5 -> 56361.864 | C22: =C17*Assumptions!$B$5 -> 75508.137 | D22: =D17*Assumptions!$B$5 -> 76376.277 | E22: =E17*Assumptions!$B$5 -> 77296.506 | F22: =F17*Assumptions!$B$5 -> 78271.948 | G22: =G17*Assumptions!$B$5 -> 79305.916 | H22: =H17*Assumptions!$B$5 -> 80401.923 | I22: =I17*Assumptions!$B$5 -> 81563.69 | ... Y22: =Y17*Assumptions!$B$5 -> 90000 | Z22: =SUM(B22:M22) -> 944417.07 | AA22: =SUM(N22:Y22) -> 1078505.6 | AB22: =SUM(B22:Y22) -> 2022922.7
A23: Install revenue (french drains only) | B23: =B22 -> 56361.864 | C23: =C22 -> 75508.137 | D23: =D22 -> 76376.277 | E23: =E22 -> 77296.506 | F23: =F22 -> 78271.948 | G23: =G22 -> 79305.916 | H23: =H22 -> 80401.923 | I23: =I22 -> 81563.69 | ... Y23: =Y22 -> 90000 | Z23: =SUM(B23:M23) -> 944417.07 | AA23: =SUM(N23:Y23) -> 1078505.6 | AB23: =SUM(B23:Y23) -> 2022922.7
A24: New Drain Check plans sold (count) | B24: =IF(1<Assumptions!$B$36,0,B17/Assumptions!$B$17*Assumptions!$B$31+IF(1<=Assumptions!$B$36+11,Assumptions!$B$34*Assumptions!$B$35/12,0)) -> 0 | C24: =IF(2<Assumptions!$B$36,0,C17/Assumptions!$B$17*Assumptions!$B$31+IF(2<=Assumptions!$B$36+11,Assumptions!$B$34*Assumptions!$B$35/12,0)) -> 0 | D24: =IF(3<Assumptions!$B$36,0,D17/Assumptions!$B$17*Assumptions!$B$31+IF(3<=Assumptions!$B$36+11,Assumptions!$B$34*Assumptions!$B$35/12,0)) -> 11.040153 | E24: =IF(4<Assumptions!$B$36,0,E17/Assumptions!$B$17*Assumptions!$B$31+IF(4<=Assumptions!$B$36+11,Assumptions!$B$34*Assumptions!$B$35/12,0)) -> 11.150581 | F24: =IF(5<Assumptions!$B$36,0,F17/Assumptions!$B$17*Assumptions!$B$31+IF(5<=Assumptions!$B$36+11,Assumptions!$B$34*Assumptions!$B$35/12,0)) -> 11.267634 | G24: =IF(6<Assumptions!$B$36,0,G17/Assumptions!$B$17*Assumptions!$B$31+IF(6<=Assumptions!$B$36+11,Assumptions!$B$34*Assumptions!$B$35/12,0)) -> 11.39171 | H24: =IF(7<Assumptions!$B$36,0,H17/Assumptions!$B$17*Assumptions!$B$31+IF(7<=Assumptions!$B$36+11,Assumptions!$B$34*Assumptions!$B$35/12,0)) -> 11.523231 | I24: =IF(8<Assumptions!$B$36,0,I17/Assumptions!$B$17*Assumptions!$B$31+IF(8<=Assumptions!$B$36+11,Assumptions!$B$34*Assumptions!$B$35/12,0)) -> 11.662643 | J24: =IF(9<Assumptions!$B$36,0,J17/Assumptions!$B$17*Assumptions!$B$31+IF(9<=Assumptions!$B$36+11,Assumptions!$B$34*Assumptions!$B$35/12,0)) -> 11.81042 | K24: =IF(10<Assumptions!$B$36,0,K17/Assumptions!$B$17*Assumptions!$B$31+IF(10<=Assumptions!$B$36+11,Assumptions!$B$34*Assumptions!$B$35/12,0)) -> 11.967063 | L24: =IF(11<Assumptions!$B$36,0,L17/Assumptions!$B$17*Assumptions!$B$31+IF(11<=Assumptions!$B$36+11,Assumptions!$B$34*Assumptions!$B$35/12,0)) -> 12.133105 | M24: =IF(12<Assumptions!$B$36,0,M17/Assumptions!$B$17*Assumptions!$B$31+IF(12<=Assumptions!$B$36+11,Assumptions!$B$34*Assumptions!$B$35/12,0)) -> 12.309109 | N24: =IF(13<Assumptions!$B$36,0,N17/Assumptions!$B$17*Assumptions!$B$31+IF(13<=Assumptions!$B$36+11,Assumptions!$B$34*Assumptions!$B$35/12,0)) -> 12.495674 | O24: =IF(14<Assumptions!$B$36,0,O17/Assumptions!$B$17*Assumptions!$B$31+IF(14<=Assumptions!$B$36+11,Assumptions!$B$34*Assumptions!$B$35/12,0)) -> 12.675 | P24: =IF(15<Assumptions!$B$36,0,P17/Assumptions!$B$17*Assumptions!$B$31+IF(15<=Assumptions!$B$36+11,Assumptions!$B$34*Assumptions!$B$35/12,0)) -> 10.8 | Q24: =IF(16<Assumptions!$B$36,0,Q17/Assumptions!$B$17*Assumptions!$B$31+IF(16<=Assumptions!$B$36+11,Assumptions!$B$34*Assumptions!$B$35/12,0)) -> 10.8 | R24: =IF(17<Assumptions!$B$36,0,R17/Assumptions!$B$17*Assumptions!$B$31+IF(17<=Assumptions!$B$36+11,Assumptions!$B$34*Assumptions!$B$35/12,0)) -> 10.8 | S24: =IF(18<Assumptions!$B$36,0,S17/Assumptions!$B$17*Assumptions!$B$31+IF(18<=Assumptions!$B$36+11,Assumptions!$B$34*Assumptions!$B$35/12,0)) -> 10.8 | T24: =IF(19<Assumptions!$B$36,0,T17/Assumptions!$B$17*Assumptions!$B$31+IF(19<=Assumptions!$B$36+11,Assumptions!$B$34*Assumptions!$B$35/12,0)) -> 10.8 | U24: =IF(20<Assumptions!$B$36,0,U17/Assumptions!$B$17*Assumptions!$B$31+IF(20<=Assumptions!$B$36+11,Assumptions!$B$34*Assumptions!$B$35/12,0)) -> 10.8 | V24: =IF(21<Assumptions!$B$36,0,V17/Assumptions!$B$17*Assumptions!$B$31+IF(21<=Assumptions!$B$36+11,Assumptions!$B$34*Assumptions!$B$35/12,0)) -> 10.8 | W24: =IF(22<Assumptions!$B$36,0,W17/Assumptions!$B$17*Assumptions!$B$31+IF(22<=Assumptions!$B$36+11,Assumptions!$B$34*Assumptions!$B$35/12,0)) -> 10.8 | X24: =IF(23<Assumptions!$B$36,0,X17/Assumptions!$B$17*Assumptions!$B$31+IF(23<=Assumptions!$B$36+11,Assumptions!$B$34*Assumptions!$B$35/12,0)) -> 10.8 | Y24: =IF(24<Assumptions!$B$36,0,Y17/Assumptions!$B$17*Assumptions!$B$31+IF(24<=Assumptions!$B$36+11,Assumptions!$B$34*Assumptions!$B$35/12,0)) -> 10.8 | Z24: =SUM(B24:M24) -> 116.25565 | AA24: =SUM(N24:Y24) -> 133.17067 | AB24: =SUM(B24:Y24) -> 249.42632
A25: Active plans (cumulative, less 8%/yr churn) | B25: =0+B24 -> 0 | C25: =B25*(1-0.08/12)+C24 -> 0 | D25: =C25*(1-0.08/12)+D24 -> 11.040153 | E25: =D25*(1-0.08/12)+E24 -> 22.117133 | F25: =E25*(1-0.08/12)+F24 -> 33.237319 | G25: =F25*(1-0.08/12)+G24 -> 44.407447 | H25: =G25*(1-0.08/12)+H24 -> 55.634628 | I25: =H25*(1-0.08/12)+I24 -> 66.926373 | J25: =I25*(1-0.08/12)+J24 -> 78.290617 | ... Y25: =X25*(1-0.08/12)+Y24 -> 232.47726
A26: Maintenance revenue (visits billed this month) | B26: =B25/12*Assumptions!$B$33*Assumptions!$B$30 -> 0 | C26: =C25/12*Assumptions!$B$33*Assumptions!$B$30 -> 0 | D26: =D25/12*Assumptions!$B$33*Assumptions!$B$30 -> 171.81239 | E26: =E25/12*Assumptions!$B$33*Assumptions!$B$30 -> 344.19788 | F26: =F25/12*Assumptions!$B$33*Assumptions!$B$30 -> 517.25578 | G26: =G25/12*Assumptions!$B$33*Assumptions!$B$30 -> 691.09089 | H26: =H25/12*Assumptions!$B$33*Assumptions!$B$30 -> 865.8139 | I26: =I25/12*Assumptions!$B$33*Assumptions!$B$30 -> 1041.5417 | ... Y26: =Y25/12*Assumptions!$B$33*Assumptions!$B$30 -> 3617.9273 | Z26: =SUM(B26:M26) -> 9579.7241 | AA26: =SUM(N26:Y26) -> 33603.68 | AB26: =SUM(B26:Y26) -> 43183.404
A27: TOTAL REVENUE | B27: =B23+B26 -> 56361.864 | C27: =C23+C26 -> 75508.137 | D27: =D23+D26 -> 76548.09 | E27: =E23+E26 -> 77640.703 | F27: =F23+F26 -> 78789.203 | G27: =G23+G26 -> 79997.007 | H27: =H23+H26 -> 81267.737 | I27: =I23+I26 -> 82605.232 | ... Y27: =Y23+Y26 -> 93617.927 | Z27: =SUM(B27:M27) -> 953996.79 | AA27: =SUM(N27:Y27) -> 1112109.3 | AB27: =SUM(B27:Y27) -> 2066106.1
A28: DIRECT COSTS
A29: Crews active | B29: =1+IF(B7>0,1,0) -> 2 | C29: =1+IF(C7>0,1,0) -> 2 | D29: =1+IF(D7>0,1,0) -> 2 | E29: =1+IF(E7>0,1,0) -> 2 | F29: =1+IF(F7>0,1,0) -> 2 | G29: =1+IF(G7>0,1,0) -> 2 | H29: =1+IF(H7>0,1,0) -> 2 | I29: =1+IF(I7>0,1,0) -> 2 | ... Y29: =1+IF(Y7>0,1,0) -> 2
A30: Crew labor (method 2: crews x wages x hours x burden; method 1: 32% of revenue) | B30: =IF(Assumptions!$B$20=1,B23*Assumptions!$B$21,B29*(Assumptions!$B$26*Assumptions!$B$27*Assumptions!$B$23+Assumptions!$B$27*Assumptions!$B$24+Assumptions!$B$26*Assumptions!$B$28*Assumptions!$B$23*1.5)*(1+Assumptions!$B$25)) -> 27808.02 | C30: =IF(Assumptions!$B$20=1,C23*Assumptions!$B$21,C29*(Assumptions!$B$26*Assumptions!$B$27*Assumptions!$B$23+Assumptions!$B$27*Assumptions!$B$24+Assumptions!$B$26*Assumptions!$B$28*Assumptions!$B$23*1.5)*(1+Assumptions!$B$25)) -> 27808.02 | D30: =IF(Assumptions!$B$20=1,D23*Assumptions!$B$21,D29*(Assumptions!$B$26*Assumptions!$B$27*Assumptions!$B$23+Assumptions!$B$27*Assumptions!$B$24+Assumptions!$B$26*Assumptions!$B$28*Assumptions!$B$23*1.5)*(1+Assumptions!$B$25)) -> 27808.02 | E30: =IF(Assumptions!$B$20=1,E23*Assumptions!$B$21,E29*(Assumptions!$B$26*Assumptions!$B$27*Assumptions!$B$23+Assumptions!$B$27*Assumptions!$B$24+Assumptions!$B$26*Assumptions!$B$28*Assumptions!$B$23*1.5)*(1+Assumptions!$B$25)) -> 27808.02 | F30: =IF(Assumptions!$B$20=1,F23*Assumptions!$B$21,F29*(Assumptions!$B$26*Assumptions!$B$27*Assumptions!$B$23+Assumptions!$B$27*Assumptions!$B$24+Assumptions!$B$26*Assumptions!$B$28*Assumptions!$B$23*1.5)*(1+Assumptions!$B$25)) -> 27808.02 | G30: =IF(Assumptions!$B$20=1,G23*Assumptions!$B$21,G29*(Assumptions!$B$26*Assumptions!$B$27*Assumptions!$B$23+Assumptions!$B$27*Assumptions!$B$24+Assumptions!$B$26*Assumptions!$B$28*Assumptions!$B$23*1.5)*(1+Assumptions!$B$25)) -> 27808.02 | H30: =IF(Assumptions!$B$20=1,H23*Assumptions!$B$21,H29*(Assumptions!$B$26*Assumptions!$B$27*Assumptions!$B$23+Assumptions!$B$27*Assumptions!$B$24+Assumptions!$B$26*Assumptions!$B$28*Assumptions!$B$23*1.5)*(1+Assumptions!$B$25)) -> 27808.02 | I30: =IF(Assumptions!$B$20=1,I23*Assumptions!$B$21,I29*(Assumptions!$B$26*Assumptions!$B$27*Assumptions!$B$23+Assumptions!$B$27*Assumptions!$B$24+Assumptions!$B$26*Assumptions!$B$28*Assumptions!$B$23*1.5)*(1+Assumptions!$B$25)) -> 27808.02 | ... Y30: =IF(Assumptions!$B$20=1,Y23*Assumptions!$B$21,Y29*(Assumptions!$B$26*Assumptions!$B$27*Assumptions!$B$23+Assumptions!$B$27*Assumptions!$B$24+Assumptions!$B$26*Assumptions!$B$28*Assumptions!$B$23*1.5)*(1+Assumptions!$B$25)) -> 27808.02 | Z30: =SUM(B30:M30) -> 333696.24 | AA30: =SUM(N30:Y30) -> 333696.24 | AB30: =SUM(B30:Y30) -> 667392.48
A31: Materials + fuel (20% of install revenue) | B31: =B23*Assumptions!$B$22 -> 11272.373 | C31: =C23*Assumptions!$B$22 -> 15101.627 | D31: =D23*Assumptions!$B$22 -> 15275.255 | E31: =E23*Assumptions!$B$22 -> 15459.301 | F31: =F23*Assumptions!$B$22 -> 15654.39 | G31: =G23*Assumptions!$B$22 -> 15861.183 | H31: =H23*Assumptions!$B$22 -> 16080.385 | I31: =I23*Assumptions!$B$22 -> 16312.738 | ... Y31: =Y23*Assumptions!$B$22 -> 18000 | Z31: =SUM(B31:M31) -> 188883.41 | AA31: =SUM(N31:Y31) -> 215701.12 | AB31: =SUM(B31:Y31) -> 404584.54
A32: Maintenance visit cost | B32: =B25/12*Assumptions!$B$33*Assumptions!$B$37 -> 0 | C32: =C25/12*Assumptions!$B$33*Assumptions!$B$37 -> 0 | D32: =D25/12*Assumptions!$B$33*Assumptions!$B$37 -> 48.30067 | E32: =E25/12*Assumptions!$B$33*Assumptions!$B$37 -> 96.762456 | F32: =F25/12*Assumptions!$B$33*Assumptions!$B$37 -> 145.41327 | G32: =G25/12*Assumptions!$B$33*Assumptions!$B$37 -> 194.28258 | H32: =H25/12*Assumptions!$B$33*Assumptions!$B$37 -> 243.4015 | I32: =I25/12*Assumptions!$B$33*Assumptions!$B$37 -> 292.80288 | ... Y32: =Y25/12*Assumptions!$B$33*Assumptions!$B$37 -> 1017.088 | Z32: =SUM(B32:M32) -> 2693.0951 | AA32: =SUM(N32:Y32) -> 9446.8177 | AB32: =SUM(B32:Y32) -> 12139.913
A33: Total direct costs | B33: =B30+B31+B32 -> 39080.393 | C33: =C30+C31+C32 -> 42909.647 | D33: =D30+D31+D32 -> 43131.576 | E33: =E30+E31+E32 -> 43364.084 | F33: =F30+F31+F32 -> 43607.823 | G33: =G30+G31+G32 -> 43863.486 | H33: =H30+H31+H32 -> 44131.806 | I33: =I30+I31+I32 -> 44413.561 | ... Y33: =Y30+Y31+Y32 -> 46825.108 | Z33: =SUM(B33:M33) -> 525272.75 | AA33: =SUM(N33:Y33) -> 558844.18 | AB33: =SUM(B33:Y33) -> 1084116.9
A34: GROSS PROFIT | B34: =B27-B33 -> 17281.472 | C34: =C27-C33 -> 32598.49 | D34: =D27-D33 -> 33416.513 | E34: =E27-E33 -> 34276.62 | F34: =F27-F33 -> 35181.381 | G34: =G27-G33 -> 36133.521 | H34: =H27-H33 -> 37135.931 | I34: =I27-I33 -> 38191.671 | ... Y34: =Y27-Y33 -> 46792.819 | Z34: =SUM(B34:M34) -> 428724.05 | AA34: =SUM(N34:Y34) -> 553265.12 | AB34: =SUM(B34:Y34) -> 981989.16
A35: Gross margin % | B35: =IF(B27=0,0,B34/B27) -> 0.30661639 | C35: =IF(C27=0,0,C34/C27) -> 0.43172155 | D35: =IF(D27=0,0,D34/D27) -> 0.43654275 | E35: =IF(E27=0,0,E34/E27) -> 0.44147745 | F35: =IF(F27=0,0,F34/F27) -> 0.4465254 | G35: =IF(G27=0,0,G34/G27) -> 0.45168591 | H35: =IF(H27=0,0,H34/H27) -> 0.45695786 | I35: =IF(I27=0,0,I34/I27) -> 0.46233961 | ... Y35: =IF(Y27=0,0,Y34/Y27) -> 0.49982755
A36: OVERHEAD
A37: Owner draw | B37: =Assumptions!$B$78 -> 12500 | C37: =Assumptions!$B$78 -> 12500 | D37: =Assumptions!$B$78 -> 12500 | E37: =Assumptions!$B$78 -> 12500 | F37: =Assumptions!$B$78 -> 12500 | G37: =Assumptions!$B$78 -> 12500 | H37: =Assumptions!$B$78 -> 12500 | I37: =Assumptions!$B$78 -> 12500 | ... Y37: =Assumptions!$B$78 -> 12500 | Z37: =SUM(B37:M37) -> 150000 | AA37: =SUM(N37:Y37) -> 150000 | AB37: =SUM(B37:Y37) -> 300000
A38: Insurance | B38: =Assumptions!$B$79 -> 900 | C38: =Assumptions!$B$79 -> 900 | D38: =Assumptions!$B$79 -> 900 | E38: =Assumptions!$B$79 -> 900 | F38: =Assumptions!$B$79 -> 900 | G38: =Assumptions!$B$79 -> 900 | H38: =Assumptions!$B$79 -> 900 | I38: =Assumptions!$B$79 -> 900 | ... Y38: =Assumptions!$B$79 -> 900 | Z38: =SUM(B38:M38) -> 10800 | AA38: =SUM(N38:Y38) -> 10800 | AB38: =SUM(B38:Y38) -> 21600
A39: Existing truck / equipment payments | B39: =Assumptions!$B$80 -> 1800 | C39: =Assumptions!$B$80 -> 1800 | D39: =Assumptions!$B$80 -> 1800 | E39: =Assumptions!$B$80 -> 1800 | F39: =Assumptions!$B$80 -> 1800 | G39: =Assumptions!$B$80 -> 1800 | H39: =Assumptions!$B$80 -> 1800 | I39: =Assumptions!$B$80 -> 1800 | ... Y39: =Assumptions!$B$80 -> 1800 | Z39: =SUM(B39:M39) -> 21600 | AA39: =SUM(N39:Y39) -> 21600 | AB39: =SUM(B39:Y39) -> 43200
A40: Software, hosting, phone, payment fees | B40: =Assumptions!$B$81 -> 350 | C40: =Assumptions!$B$81 -> 350 | D40: =Assumptions!$B$81 -> 350 | E40: =Assumptions!$B$81 -> 350 | F40: =Assumptions!$B$81 -> 350 | G40: =Assumptions!$B$81 -> 350 | H40: =Assumptions!$B$81 -> 350 | I40: =Assumptions!$B$81 -> 350 | ... Y40: =Assumptions!$B$81 -> 350 | Z40: =SUM(B40:M40) -> 4200 | AA40: =SUM(N40:Y40) -> 4200 | AB40: =SUM(B40:Y40) -> 8400
A41: Bookkeeping / CPA | B41: =Assumptions!$B$82 -> 250 | C41: =Assumptions!$B$82 -> 250 | D41: =Assumptions!$B$82 -> 250 | E41: =Assumptions!$B$82 -> 250 | F41: =Assumptions!$B$82 -> 250 | G41: =Assumptions!$B$82 -> 250 | H41: =Assumptions!$B$82 -> 250 | I41: =Assumptions!$B$82 -> 250 | ... Y41: =Assumptions!$B$82 -> 250 | Z41: =SUM(B41:M41) -> 3000 | AA41: =SUM(N41:Y41) -> 3000 | AB41: =SUM(B41:Y41) -> 6000
...

Sheet Unit economics
A1: Unit economics - one job, one crew-month, one maintenance customer
A2: ONE JOB (average)
A3: Linear feet | B3: =Assumptions!$B$17 -> 100
A4: Price to customer | B4: =B3*Assumptions!$B$5 -> 5000
A5: Crew labor (share of one crew-month, at target LF) | B5: =B3/Assumptions!$B$13*(Assumptions!$B$26*Assumptions!$B$27*Assumptions!$B$23+Assumptions!$B$27*Assumptions!$B$24+Assumptions!$B$26*Assumptions!$B$28*Assumptions!$B$23*1.5)*(1+Assumptions!$B$25) -> 1544.89
A6: Materials + fuel (20%) | B6: =B4*Assumptions!$B$22 -> 1000
A7: Gross profit per job | B7: =B4-B5-B6 -> 2455.11
A8: Gross margin | B8: =B7/B4 -> 0.491022
A9: Crew days per job (at target LF/month) | B9: =B3/(Assumptions!$B$13/Assumptions!$B$10) -> 2.3333333
A10: ONE CREW-MONTH (at target)
A11: LF per month | B11: =Assumptions!$B$13 -> 900
A12: Revenue per crew-month | B12: =B11*Assumptions!$B$5 -> 45000
A13: Crew wages before burden (size x hours x $/hr + lead premium + OT) | B13: =Assumptions!$B$26*Assumptions!$B$27*Assumptions!$B$23+Assumptions!$B$27*Assumptions!$B$24+Assumptions!$B$26*Assumptions!$B$28*Assumptions!$B$23*1.5 -> 12196.5
A14: Crew wages with burden (the fixed cost of a crew) | B14: =B13*(1+Assumptions!$B$25) -> 13904.01
A15: Labor as % of revenue at target (Charlie's rule of thumb: 32%) | B15: =B14/B12 -> 0.308978 | C15: Fixed crew cost divided by revenue: the crew costs the same at 400 LF or 900 LF, so every extra foot per day drops straight to margin.
A16: Gross profit per crew-month | B16: =B12*(1-Assumptions!$B$22)-B14 -> 22095.99
A17: ONE MAINTENANCE CUSTOMER
A18: Plan price per visit | B18: =Assumptions!$B$30 -> 249
A19: Cost per visit | B19: =Assumptions!$B$37 -> 70
A20: Gross profit per visit | B20: =B18-B19 -> 179
A21: Gross margin per visit | B21: =B20/B18 -> 0.7188755
A22: Visits over 5 years | B22: =5*Assumptions!$B$33 -> 3.75
A23: 5-year gross profit per plan customer | B23: =B20*B22 -> 671.25
A24: Referral value: 1 in 4 plan customers refers one job | B24: =0.25*B7 -> 613.7775 | C24: Not in the proforma - upside only.
A25: TODAY vs TARGET (productivity is the margin)
A26: Today: LF per month (Charlie, before Ned) | B26: =Assumptions!$B$6 -> 400
A27: Today: revenue per crew-month (drain LF x $/LF + other-work days x $/day) | B27: =B26*Assumptions!$B$5+MAX(0,Assumptions!$B$10-B26/Assumptions!$B$11)*Assumptions!$B$12 -> 31697.674
A28: Today: revenue per crew-day (model) vs Charlie's $1,500 | B28: =B27/Assumptions!$B$10 -> 1509.4131 | C28: Charlie today: about 9 crew-days on drains, 12 on other work to fill the month - matches his $1,500/day. The plan below replaces those 12 other-work days with drains too.
A29: Today: labor as % of revenue | B29: =B14/B27 -> 0.43864448 | C29: At today's 400 LF the crew is expensive relative to revenue; at 900 LF it is not. That gap is the whole growth case.
A30: Target: labor as % of revenue | B30: =B15 -> 0.308978
A31: Fixed monthly overhead before any crew (owner draw, existing payments, software, bookkeeping, shop) | B31: =Assumptions!$B$78+Assumptions!$B$80+Assumptions!$B$81+Assumptions!$B$82+Assumptions!$B$83 -> 15500
A32: Break-even LF per month, one crew (fixed overhead + one crew's cost + its insurance, after materials) | B32: =(B31+B14+Assumptions!$B$79)/(Assumptions!$B$5*(1-Assumptions!$B$22)) -> 757.60025
A33: Break-even as % of one crew's target | B33: =B32/Assumptions!$B$13 -> 0.84177806

Sheet Scenarios
A1: Three scenarios - year-2 run rate (month 24) and 24-month totals
A2: Change the blue cells; everything below recalculates using the same cost structure as the proforma.
B4: Conservative | C4: Base (Charlie's goal) | D4: Stretch
A5: LF per crew per month | B5: 700 | C5: 900 | D5: 1000
A6: Crews running by month 24 | B6: 1 | C6: 2 | D6: 2
A7: Average $/LF | B7: 45 | C7: 50 | D7: 55
A8: Active Drain Check plans at month 24 | B8: 40 | C8: 90 | D8: 140
A9: Monthly install revenue | B9: =B5*B6*B7 -> 31500 | C9: =C5*C6*C7 -> 90000 | D9: =D5*D6*D7 -> 110000
A10: Monthly maintenance revenue | B10: =B8/12*Assumptions!$B$33*Assumptions!$B$30 -> 622.5 | C10: =C8/12*Assumptions!$B$33*Assumptions!$B$30 -> 1400.625 | D10: =D8/12*Assumptions!$B$33*Assumptions!$B$30 -> 2178.75
A11: Monthly revenue | B11: =B9+B10 -> 32122.5 | C11: =C9+C10 -> 91400.625 | D11: =D9+D10 -> 112178.75
A12: Gross profit (installs less materials and crew wages; plans at plan margin) | B12: =B9*(1-Assumptions!$B$22)-B6*(Assumptions!$B$26*Assumptions!$B$27*Assumptions!$B$23+Assumptions!$B$27*Assumptions!$B$24+Assumptions!$B$26*Assumptions!$B$28*Assumptions!$B$23*1.5)*(1+Assumptions!$B$25)+B10*(1-Assumptions!$B$37/Assumptions!$B$30) -> 11743.49 | C12: =C9*(1-Assumptions!$B$22)-C6*(Assumptions!$B$26*Assumptions!$B$27*Assumptions!$B$23+Assumptions!$B$27*Assumptions!$B$24+Assumptions!$B$26*Assumptions!$B$28*Assumptions!$B$23*1.5)*(1+Assumptions!$B$25)+C10*(1-Assumptions!$B$37/Assumptions!$B$30) -> 45198.855 | D12: =D9*(1-Assumptions!$B$22)-D6*(Assumptions!$B$26*Assumptions!$B$27*Assumptions!$B$23+Assumptions!$B$27*Assumptions!$B$24+Assumptions!$B$26*Assumptions!$B$28*Assumptions!$B$23*1.5)*(1+Assumptions!$B$25)+D10*(1-Assumptions!$B$37/Assumptions!$B$30) -> 61758.23
A13: Overhead (one crew) / (two crews incl. loan) | B13: =IF(B6=1,'Proforma 24 mo'!D50,'Proforma 24 mo'!Y50) -> 25763.638 | C13: =IF(C6=1,'Proforma 24 mo'!D50,'Proforma 24 mo'!Y50) -> 23525.026 | D13: =IF(D6=1,'Proforma 24 mo'!D50,'Proforma 24 mo'!Y50) -> 23525.026
A14: Operating profit per month | B14: =B12-B13 -> -14020.148 | C14: =C12-C13 -> 21673.829 | D14: =D12-D13 -> 38233.204
A15: Operating profit per year (run rate) | B15: =B14*12 -> -168241.77 | C15: =C14*12 -> 260085.95 | D15: =D14*12 -> 458798.45
A16: Operating margin | B16: =IF(B11=0,0,B14/B11) -> -0.43645879 | C16: =IF(C11=0,0,C14/C11) -> 0.23712999 | D16: =IF(D11=0,0,D14/D11) -> 0.34082395
A17: Estimates needed per month (jobs / Charlie's close rate) | B17: =B5*B6/Assumptions!$B$17/Assumptions!$B$74 -> 10 | C17: =C5*C6/Assumptions!$B$17/Assumptions!$B$74 -> 25.714286 | D17: =D5*D6/Assumptions!$B$17/Assumptions!$B$74 -> 28.571429
A18: Leads needed per month (at ~45% of leads booking an estimate) | B18: =B17/0.45 -> 22.222222 | C18: =C17/0.45 -> 57.142857 | D18: =D17/0.45 -> 63.492063
A19: What has to be true
A20: Conservative: one crew at 700 LF and $45/LF still clears overhead - the plan fails safe.
A21: Base: two crews at 900 LF, $50/LF, 90 plan customers - Charlie's stated goal, reached in month 10-12 of the proforma. Close rate on estimates is Charlie's 70% (Assumptions, yellow cell).
A22: Stretch: pricing power from reviews + Moasure proposals lifts $/LF to $55; 140 plan customers = the sellable recurring book.

Sheet Equipment plan
A1: Path to owning Crew 2's equipment - rent first, buy on proof
A2: Crew 1 already owns a big trailer, a skid steer and a mini excavator (no capex in this plan). Crew 2 needs its own set. Rent-to-prove, then buy; every date is driven by the Crew 2 start month on Assumptions.
A4: Item | B4: Purchase price | C4: Rent / month | D4: Months rented | E4: Rent paid before buying | F4: Purchase month | G4: Down payment (20%) | H4: Loan payment / mo | I4: Loan paid off (month) | J4: Own-vs-rent break-even (months)
A5: Mini excavator (used) | B5: =Assumptions!$B$90 -> 50000 | C5: =Assumptions!$B$91 -> 2000 | D5: =Assumptions!$B$92 -> 3 | E5: =C5*D5 -> 6000 | F5: =Assumptions!$B$14+D5 -> 4 | G5: =B5*(1-Assumptions!$B$105) -> 10000 | H5: =-PMT(Assumptions!$B$106/12,Assumptions!$B$107,B5*Assumptions!$B$105) -> 830.33421 | I5: =F5+Assumptions!$B$107 -> 64 | J5: =IF(C5=0,"n/a",B5/C5) -> 25
A6: Skid steer / CTL (used) | B6: =Assumptions!$B$93 -> 38000 | C6: =Assumptions!$B$94 -> 1700 | D6: =Assumptions!$B$95 -> 3 | E6: =C6*D6 -> 5100 | F6: =Assumptions!$B$14+D6 -> 4 | G6: =B6*(1-Assumptions!$B$105) -> 7600 | H6: =-PMT(Assumptions!$B$106/12,Assumptions!$B$107,B6*Assumptions!$B$105) -> 631.054 | I6: =F6+Assumptions!$B$107 -> 64 | J6: =IF(C6=0,"n/a",B6/C6) -> 22.352941
A7: Dump trailer 7x14 (new) | B7: =Assumptions!$B$96 -> 9500 | C7: =Assumptions!$B$97 -> 600 | D7: =Assumptions!$B$98 -> 0 | E7: =C7*D7 -> 0 | F7: =Assumptions!$B$14+D7 -> 1 | G7: =B7*(1-Assumptions!$B$105) -> 1900 | H7: =-PMT(Assumptions!$B$106/12,Assumptions!$B$107,B7*Assumptions!$B$105) -> 157.7635 | I7: =F7+Assumptions!$B$107 -> 61 | J7: =IF(C7=0,"n/a",B7/C7) -> 15.833333
A8: Truck 3/4-ton (used) | B8: =Assumptions!$B$99 -> 35000 | C8: =Assumptions!$B$100 -> 0 | D8: =Assumptions!$B$101 -> 0 | E8: =C8*D8 -> 0 | F8: =Assumptions!$B$14+D8 -> 1 | G8: =B8*(1-Assumptions!$B$105) -> 7000 | H8: =-PMT(Assumptions!$B$106/12,Assumptions!$B$107,B8*Assumptions!$B$105) -> 581.23395 | I8: =F8+Assumptions!$B$107 -> 61 | J8: =IF(C8=0,"n/a",B8/C8) -> n/a
A9: Tools, laser, compactor, PPE | B9: =Assumptions!$B$102 -> 6000 | C9: =Assumptions!$B$103 -> 0 | D9: =Assumptions!$B$104 -> 0 | E9: =C9*D9 -> 0 | F9: =Assumptions!$B$14+D9 -> 1 | G9: =B9*(1-Assumptions!$B$105) -> 1200 | H9: =-PMT(Assumptions!$B$106/12,Assumptions!$B$107,B9*Assumptions!$B$105) -> 99.640105 | I9: =F9+Assumptions!$B$107 -> 61 | J9: =IF(C9=0,"n/a",B9/C9) -> n/a
A10: Total | B10: =SUM(B5:B9) -> 138500 | E10: =SUM(E5:E9) -> 11100 | G10: =SUM(G5:G9) -> 27700 | H10: =SUM(H5:H9) -> 2300.0258
A12: How to read it
A13: Own-vs-rent break-even: purchase price / monthly rent. A mini-ex at $50,000 vs $2,000/month breaks even at 25 months of use - so anything Crew 2 will run for more than two years should be owned; the 3-month rental is insurance against Crew 2 not working out, not a long-term plan.
A14: The purchase month is the Crew 2 start month plus the months rented. Decision rule for pulling the trigger early or late: buy when Crew 2 has installed its target LF in two consecutive months; keep renting if it has not.
A15: Down payments hit cash in the purchase month (Proforma: 'Cash out - Crew 2 down payments'); loan payments run 60 months from there. Rent paid before buying is money spent to de-risk the purchase - budgeted, not wasted.
A16: Crew 1's set is already owned: no purchases are modeled for it. Its existing payments, if any, sit in 'Existing truck / equipment payments' on Assumptions.
A17: Time to full ownership of Crew 2's set: trailer, truck and tools on day one; mini-ex and skid steer bought in month start+3; all loans paid off 60 months after that (month 64 in the base case, since both crews now launch in month 1). Equity builds from the first payment; the machines outlast the loans.

Sheet 5-year plan
A1: Five-year plan - annual, safe-scaling (Year 1-2 pull from the 24-month proforma; Years 3-5 from the blue inputs below)
A2: Blue = input. Every year is gated: the next crew is added only when the previous one has run at target for 3 months, backlog > 4 weeks, and cash > 2 months of overhead.
B4: Today (run rate) | C4: Year 1 | D4: Year 2 | E4: Year 3 | F4: Year 4 | G4: Year 5 | H4: Notes
A5: CAPACITY
A6: Crews at year end | B6: 1 | C6: 2 | D6: 2 | E6: 3 | F6: 4 | G6: 4 | H6: Today = Charlie's one crew before Ned. Both crews launch together in year 1, funded by the initial investment; Crew 3 in year 3, Crew 4 in year 4, then consolidate. Change to test a slower or faster path.
A7: Average crews running during the year | B7: 1 | C7: 2 | D7: 2 | E7: 2.5 | F7: 3.5 | G7: 4 | H7: Both crews run the whole of year 1 - no ramp. Crew 3 starts mid-year 3; Crew 4 mid-year 4.
A8: LF per crew per year at target x utilization | B8: 4800 | C8: ='Proforma 24 mo'!Z17/C7 -> 9444.1707 | D8: ='Proforma 24 mo'!AA17/D7 -> 10785.056 | E8: =Assumptions!$B$13*12*0.95 -> 10260 | F8: =Assumptions!$B$13*12*0.95 -> 10260 | G8: =Assumptions!$B$13*12*0.95 -> 10260 | H8: Today = 400 LF x 12. Years 3-5: 900 LF x 12 x 95% utilization.
A9: Total LF installed | B9: =B7*B8 -> 4800 | C9: ='Proforma 24 mo'!Z17 -> 18888.341 | D9: ='Proforma 24 mo'!AA17 -> 21570.112 | E9: =E7*E8 -> 25650 | F9: =F7*F8 -> 35910 | G9: =G7*G8 -> 41040
A10: REVENUE
A11: Average $/LF (3% a year after year 2 - reviews and the map justify it) | B11: =Assumptions!$B$5 -> 50 | C11: =Assumptions!$B$5 -> 50 | D11: =Assumptions!$B$5 -> 50 | E11: =D11*1.03 -> 51.5 | F11: =E11*1.03 -> 53.045 | G11: =F11*1.03 -> 54.63635
A12: Drainage install revenue (french drains only) | B12: ='Unit economics'!B27*12 -> 380372.09 | C12: ='Proforma 24 mo'!Z23 -> 944417.07 | D12: ='Proforma 24 mo'!AA23 -> 1078505.6 | E12: =E9*E11 -> 1320975 | F12: =F9*F11 -> 1904845.9 | G12: =G9*G11 -> 2242275.8 | H12: Today's column is Charlie's actual mix of drain and other work (Unit economics tab); years 1-5 of the plan are drains only.
A13: Drain Check active plans at year end | B13: 0 | C13: ='Proforma 24 mo'!M25 -> 112.90458 | D13: ='Proforma 24 mo'!Y25 -> 232.47726 | E13: 355 | F13: 540 | G13: 745 | H13: 60% of customers take a cleaning plan (half yearly, half every two years); about 8%/yr churn. Years 1-2 come from the 24-month proforma.
A14: Drain Check revenue | B14: 0 | C14: ='Proforma 24 mo'!Z26 -> 9579.7241 | D14: ='Proforma 24 mo'!AA26 -> 33603.68 | E14: =(D13+E13)/2*Assumptions!$B$30 -> 73140.918 | F14: =(E13+F13)/2*Assumptions!$B$30*1.03 -> 114770.32 | G14: =(F13+G13)/2*Assumptions!$B$30*1.06 -> 169581.45
A15: TOTAL REVENUE | B15: =B12+B14 -> 380372.09 | C15: =C12+C14 -> 953996.79 | D15: =D12+D14 -> 1112109.3 | E15: =E12+E14 -> 1394115.9 | F15: =F12+F14 -> 2019616.3 | G15: =G12+G14 -> 2411857.3
A16: DIRECT COSTS
A17: Crew labor (crews x fixed crew cost; wages +3%/yr from year 3) | B17: =B7*(Assumptions!$B$26*Assumptions!$B$27*Assumptions!$B$23+Assumptions!$B$27*Assumptions!$B$24)*(1+Assumptions!$B$25)*12 -> 166848.12 | C17: ='Proforma 24 mo'!Z30 -> 333696.24 | D17: ='Proforma 24 mo'!AA30 -> 333696.24 | E17: =E7*(Assumptions!$B$26*Assumptions!$B$27*Assumptions!$B$23+Assumptions!$B$27*Assumptions!$B$24)*(1+Assumptions!$B$25)*12*1.03 -> 429633.91 | F17: =F7*(Assumptions!$B$26*Assumptions!$B$27*Assumptions!$B$23+Assumptions!$B$27*Assumptions!$B$24)*(1+Assumptions!$B$25)*12*1.03^2 -> 619532.1 | G17: =G7*(Assumptions!$B$26*Assumptions!$B$27*Assumptions!$B$23+Assumptions!$B$27*Assumptions!$B$24)*(1+Assumptions!$B$25)*12*1.03^3 -> 729277.78 | H17: Change the wage on Assumptions and every year moves.
A18: Materials + fuel (20% of install revenue) | B18: =B12*Assumptions!$B$22 -> 76074.419 | C18: ='Proforma 24 mo'!Z31 -> 188883.41 | D18: ='Proforma 24 mo'!AA31 -> 215701.12 | E18: =E12*Assumptions!$B$22 -> 264195 | F18: =F12*Assumptions!$B$22 -> 380969.19 | G18: =G12*Assumptions!$B$22 -> 448455.16
A19: Drain Check visit costs | B19: 0 | C19: ='Proforma 24 mo'!Z32 -> 2693.0951 | D19: ='Proforma 24 mo'!AA32 -> 9446.8177 | E19: =E14/Assumptions!$B$30*Assumptions!$B$37 -> 20561.704 | F19: =F14/Assumptions!$B$30/1.03*Assumptions!$B$37 -> 31325 | G19: =G14/Assumptions!$B$30/1.06*Assumptions!$B$37 -> 44975
A20: GROSS PROFIT | B20: =B15-B17-B18-B19 -> 137449.55 | C20: =C15-C17-C18-C19 -> 428724.05 | D20: =D15-D17-D18-D19 -> 553265.12 | E20: =E15-E17-E18-E19 -> 679725.31 | F20: =F15-F17-F18-F19 -> 987789.99 | G20: =G15-G17-G18-G19 -> 1189149.3
A21: Gross margin | B21: =IF(B15=0,0,B20/B15) -> 0.36135552 | C21: =IF(C15=0,0,C20/C15) -> 0.44939778 | D21: =IF(D15=0,0,D20/D15) -> 0.49749167 | E21: =IF(E15=0,0,E20/E15) -> 0.48756728 | F21: =IF(F15=0,0,F20/F15) -> 0.48909786 | G21: =IF(G15=0,0,G20/G15) -> 0.49304299
A22: OVERHEAD - the layers that let the company handle the volume
A23: Owner draw (years 3-5 step up with the company, proportional to the year-1 draw) | B23: =Assumptions!$B$78*12 -> 150000 | C23: =Assumptions!$B$78*12 -> 150000 | D23: =Assumptions!$B$78*12 -> 150000 | E23: =Assumptions!$B$78*12*1.16667 -> 175000.5 | F23: =Assumptions!$B$78*12*1.33333 -> 199999.5 | G23: =Assumptions!$B$78*12*1.5 -> 225000 | H23: Charlie's pay rises with the company - change the Owner draw cell on Assumptions and all six years move together, in the same proportion. Before write-offs - see the Write-offs and taxes tab for what this actually costs him after deductions.
A24: Office admin / bookkeeper (part-time year 2, full-time year 3) | B24: 0 | C24: 0 | D24: 24000 | E24: 42000 | F24: 48000 | G24: 50000 | H24: Answers the phone the software cannot, books, AP/AR, reviews, scheduling. Hire when two crews are running.
A25: Operations manager (runs crews, purchasing, quality) | B25: 0 | C25: 0 | D25: 0 | E25: 48750 | F25: 70000 | G25: 72000 | H25: Hired in month 4 of year 3 (about $65K/yr), before Crew 3 starts, so Charlie is not the bottleneck at three crews. Usually the best crew lead, promoted.
A26: Estimator / sales (runs Moasure surveys and quotes) | B26: 0 | C26: 0 | D26: 0 | E26: 0 | F26: 55000 | G26: 58000 | H26: At four crews Charlie cannot run 40+ estimates a month alone. Base + commission.
A27: Crew-lead bonus pool (LF/day and callbacks) | B27: 0 | C27: 0 | D27: 6000 | E27: 12000 | F27: 18000 | G27: 20000 | H27: $500/quarter per lead when the crew beats 43 LF/day with no callbacks.
A28: Insurance - GL, auto, equipment, WC excess (per crew) | B28: =Assumptions!$B$79*12 -> 10800 | C28: ='Proforma 24 mo'!Z38 -> 10800 | D28: ='Proforma 24 mo'!AA38 -> 10800 | E28: =Assumptions!$B$79*12+9000*(E6-1) -> 28800 | F28: =Assumptions!$B$79*12+9000*(F6-1) -> 37800 | G28: =Assumptions!$B$79*12+9000*(G6-1) -> 37800 | H28: Today's premium plus about $9K per additional crew (auto, equipment, WC); get quotes before each hire.
A29: Truck + equipment loan payments (existing + one set per crew) | B29: =Assumptions!$B$80*12 -> 21600 | C29: ='Proforma 24 mo'!Z39+'Proforma 24 mo'!Z49 -> 44816.144 | D29: ='Proforma 24 mo'!AA39+'Proforma 24 mo'!AA49 -> 49200.309 | E29: =Assumptions!$B$80*12+'Equipment plan'!H10*12*(E6-1) -> 76800.618 | F29: =Assumptions!$B$80*12+'Equipment plan'!H10*12*(F6-1) -> 104400.93 | G29: =Assumptions!$B$80*12+'Equipment plan'!H10*12*(G6-1) -> 104400.93 | H29: Each new crew carries its own set (Equipment plan tab); rent-first 3 months before each purchase.
A30: Yard space used (sq ft) - Cottondale | B30: 0 | C30: =Assumptions!$B$84 -> 2500 | D30: =Assumptions!$B$84 -> 2500 | E30: 3000 | F30: 4000 | G30: 4000 | H30: About 1,000 sq ft more per crew for its set and material bins. Years 1-2 follow the Assumptions tab.
A31: Yard rent rate ($ per sq ft per month) | B31: 0 | C31: =Assumptions!$B$85 -> 0.85 | D31: =Assumptions!$B$85 -> 0.85 | E31: =D31*1.05 -> 0.8925 | F31: =E31*1.05 -> 0.937125 | G31: =F31*1.05 -> 0.98398125 | H31: Steps up 5%/yr from year 3 (change the multiplier); market in 70815 is about $1.19.
A32: Yard / shop rent (sq ft x rate x 12) | B32: =B30*B31*12 -> 0 | C32: ='Proforma 24 mo'!Z43 -> 25500 | D32: ='Proforma 24 mo'!AA43 -> 25500 | E32: =E30*E31*12 -> 32130 | F32: =F30*F31*12 -> 44982 | G32: =G30*G31*12 -> 47231.1 | H32: Years 1-2 from the proforma (start month applies).
A33: Software, phones, hosting, payment fees (+ per crew) | B33: =Assumptions!$B$81*12 -> 4200 | C33: ='Proforma 24 mo'!Z40 -> 4200 | D33: ='Proforma 24 mo'!AA40 -> 4200 | E33: =4200+1200*E6 -> 7800 | F33: =4200+1200*F6 -> 9000 | G33: =4200+1200*G6 -> 9000
A34: Bookkeeping / CPA / payroll service | B34: =Assumptions!$B$82*12 -> 3000 | C34: ='Proforma 24 mo'!Z41 -> 3000 | D34: ='Proforma 24 mo'!AA41 -> 3000 | E34: 7200 | F34: 9000 | G34: 9600 | H34: QuickBooks Online + payroll service + monthly close; CPA quarterly. Grows with headcount.
A35: Marketing (Google LSA, Meta, content) - ~5% of revenue from year 3 | B35: =(Assumptions!$B$64+Assumptions!$B$67+Assumptions!$B$76)*12 -> 21600 | C35: ='Proforma 24 mo'!Z45+'Proforma 24 mo'!Z46+'Proforma 24 mo'!Z47 -> 31440 | D35: ='Proforma 24 mo'!AA45+'Proforma 24 mo'!AA46+'Proforma 24 mo'!AA47 -> 32400 | E35: =E15*0.05 -> 69705.796 | F35: =F15*0.05 -> 100980.81 | G35: =G15*0.045 -> 108533.58 | H35: Falls as a % of revenue as reviews, referrals and the plan book compound.
A36: Shop, tools, uniforms, training, misc (+ per crew) | B36: =Assumptions!$B$83*12 -> 7200 | C36: ='Proforma 24 mo'!Z42 -> 7200 | D36: ='Proforma 24 mo'!AA42 -> 7200 | E36: =7200+3000*E6 -> 16200 | F36: =7200+3000*F6 -> 19200 | G36: =7200+3000*G6 -> 19200
A37: Crew hiring, training and rent-first equipment months (per new crew) | B37: 0 | C37: ='Proforma 24 mo'!Z48 -> 15600 | D37: ='Proforma 24 mo'!AA48 -> 0 | E37: =(E6-D6)*('Equipment plan'!E10+Assumptions!$B$108) -> 15600 | F37: =(F6-E6)*('Equipment plan'!E10+Assumptions!$B$108) -> 15600 | G37: =(G6-F6)*('Equipment plan'!E10+Assumptions!$B$108) -> 0
A38: GROWTH & OPERATIONS LEAD (Ned) - proposed, for discussion
A39: Base ($/yr) - fractional, about 25 hours a week | B39: 0 | C39: =Assumptions!$B$144 -> 60000 | D39: =Assumptions!$B$144 -> 60000 | E39: =Assumptions!$B$145 -> 66000 | F39: =Assumptions!$B$146 -> 72000 | G39: =Assumptions!$B$146 -> 72000 | H39: Pulled straight from the Ned assumptions above - change those cells and this tab and the Ned proforma tab move together. For scale: Baton Rouge general/operations managers average $129,840 full-time (BLS OEWS).
A40: Growth share - % of operating profit above the baseline year | B40: 0 | C40: =Assumptions!$B$121 -> 0.1 | D40: =Assumptions!$B$121 -> 0.1 | E40: =Assumptions!$B$121 -> 0.1 | F40: =Assumptions!$B$121 -> 0.1 | G40: =Assumptions!$B$121 -> 0.1 | H40: Paid only on profit above what the business makes today; nothing on the baseline. Same cell as the Ned proforma tab.
A41: Baseline operating profit (today's run rate after owner draw, floored at 0) | B41: =MAX(0,B45) -> 0 | C41: =MAX(0,B45) -> 0 | D41: =MAX(0,B45) -> 0 | E41: =MAX(0,B45) -> 0 | F41: =MAX(0,B45) -> 0 | G41: =MAX(0,B45) -> 0 | H41: Today's column, computed below. The share is earned only on profit the growth creates.
...

Sheet Three cases 5-yr
A1: Worst case, conservative, strong - the same business run three ways
A2: Blue = change it. The middle block is the plan in the blueprint. Today's run rate is on the '5-year plan' tab and is the same in all three cases; what differs is only how fast crews fill their days, what a foot sells for, how many plans attach, and when a crew is added.
A4: Side by side
B5: Worst case | C5: Conservative | D5: Strong
A6: Revenue - year 1 | B6: =B37 -> 879315.75 | C6: =B69 -> 1101154.5 | D6: =B101 -> 1282261.5
A7: Revenue - year 5 | B7: =F37 -> 1135327.5 | C7: =F69 -> 2578331.4 | D7: =F101 -> 3717092.7
